Workbook

Sheet Call Arraivals
B1: Arraivals for last 6 weeks | AT1: Avg of Arrivals for last 6 weeks | BC1: Percentage for AVG of arrivals for last 6 weeks
B2: Intervals | C2: Sun | D2: Mon | E2: Tue | F2: Wed | G2: Thu | H2: Fri | I2: Sat | J2: Sun | K2: Mon | L2: Tue | M2: Wed | N2: Thu | O2: Fri | P2: Sat | Q2: Sun | R2: Mon | S2: Tue | T2: Wed | U2: Thu | V2: Fri | W2: Sat | X2: Sun | Y2: Mon | Z2: Tue | AA2: Wed | AB2: Thu | AC2: Fri | AD2: Sat | AE2: Sun | AF2: Mon | AG2: Tue | AH2: Wed | AI2: Thu | AJ2: Fri | AK2: Sat | AL2: Sun | AM2: Mon | AN2: Tue | AO2: Wed | AP2: Thu | AQ2: Fri | AR2: Sat | AT2: Intervals | AU2: Sun | AV2: Mon | AW2: Tue | AX2: Wed | AY2: Thu | AZ2: Fri | BA2: Sat | BC2: Intervals | BD2: Sun | BE2: Mon | BF2: Tue | BG2: Wed | BH2: Thu | BI2: Fri | BJ2: Sat
B3: 0.375 | C3: 70 | D3: 56 | E3: 63 | F3: 57 | G3: 50 | H3: 36 | I3: 30 | J3: 71 | K3: 57 | L3: 64 | M3: 58 | N3: 51 | O3: 37 | P3: 31 | Q3: 72 | R3: 58 | S3: 65 | T3: 59 | U3: 52 | V3: 37 | W3: 31 | X3: 69 | Y3: 55 | Z3: 62 | AA3: 56 | AB3: 49 | AC3: 35 | AD3: 29 | AE3: 68 | AF3: 54 | AG3: 61 | AH3: 55 | AI3: 48 | AJ3: 34 | AK3: 28 | AL3: 69 | AM3: 56 | AN3: 62 | AO3: 57 | AP3: 49 | AQ3: 35 | AR3: 30 | AT3: 0.375 | AU3: =AVERAGEIF($C$2:$AR$2,AU$2,$C3:$AR3) -> 69.833333 | AV3: =AVERAGEIF($C$2:$AR$2,AV$2,$C3:$AR3) -> 56 | AW3: =AVERAGEIF($C$2:$AR$2,AW$2,$C3:$AR3) -> 62.833333 | AX3: =AVERAGEIF($C$2:$AR$2,AX$2,$C3:$AR3) -> 57 | AY3: =AVERAGEIF($C$2:$AR$2,AY$2,$C3:$AR3) -> 49.833333 | AZ3: =AVERAGEIF($C$2:$AR$2,AZ$2,$C3:$AR3) -> 35.666667 | BA3: =AVERAGEIF($C$2:$AR$2,BA$2,$C3:$AR3) -> 29.833333 | BC3: 0.375 | BD3: =AU3/AU$33 -> 0.03495745 | BE3: =AV3/AV$33 -> 0.030746706 | BF3: =AW3/AW$33 -> 0.035079557 | BG3: =AX3/AX$33 -> 0.031413613 | BH3: =AY3/AY$33 -> 0.031055256 | BI3: =AZ3/AZ$33 -> 0.030115395 | BJ3: =BA3/BA$33 -> 0.029586777
B4: 0.39583333 | C4: 80 | D4: 77 | E4: 73 | F4: 71 | G4: 61 | H4: 45 | I4: 33 | J4: 81 | K4: 78 | L4: 74 | M4: 72 | N4: 62 | O4: 46 | P4: 34 | Q4: 82 | R4: 79 | S4: 75 | T4: 73 | U4: 63 | V4: 47 | W4: 34 | X4: 79 | Y4: 76 | Z4: 72 | AA4: 70 | AB4: 60 | AC4: 44 | AD4: 32 | AE4: 78 | AF4: 75 | AG4: 71 | AH4: 69 | AI4: 59 | AJ4: 43 | AK4: 31 | AL4: 79 | AM4: 76 | AN4: 73 | AO4: 71 | AP4: 60 | AQ4: 44 | AR4: 32 | AT4: 0.39583333 | AU4: =AVERAGEIF($C$2:$AR$2,AU$2,$C4:$AR4) -> 79.833333 | AV4: =AVERAGEIF($C$2:$AR$2,AV$2,$C4:$AR4) -> 76.833333 | AW4: =AVERAGEIF($C$2:$AR$2,AW$2,$C4:$AR4) -> 73 | AX4: =AVERAGEIF($C$2:$AR$2,AX$2,$C4:$AR4) -> 71 | AY4: =AVERAGEIF($C$2:$AR$2,AY$2,$C4:$AR4) -> 60.833333 | AZ4: =AVERAGEIF($C$2:$AR$2,AZ$2,$C4:$AR4) -> 44.833333 | BA4: =AVERAGEIF($C$2:$AR$2,BA$2,$C4:$AR4) -> 32.666667 | BC4: 0.39583333 | BD4: =AU4/AU$33 -> 0.039963291 | BE4: =AV4/AV$33 -> 0.042185212 | BF4: =AW4/AW$33 -> 0.04075556 | BG4: =AX4/AX$33 -> 0.039129237 | BH4: =AY4/AY$33 -> 0.037910262 | BI4: =AZ4/AZ$33 -> 0.037855334 | BJ4: =BA4/BA$33 -> 0.032396694
B5: 0.41666667 | C5: 85 | D5: 78 | E5: 78 | F5: 78 | G5: 67 | H5: 53 | I5: 34 | J5: 86 | K5: 79 | L5: 79 | M5: 79 | N5: 68 | O5: 54 | P5: 35 | Q5: 87 | R5: 80 | S5: 80 | T5: 80 | U5: 69 | V5: 55 | W5: 35 | X5: 84 | Y5: 77 | Z5: 77 | AA5: 77 | AB5: 66 | AC5: 52 | AD5: 33 | AE5: 83 | AF5: 76 | AG5: 76 | AH5: 76 | AI5: 65 | AJ5: 51 | AK5: 32 | AL5: 84 | AM5: 77 | AN5: 77 | AO5: 78 | AP5: 66 | AQ5: 52 | AR5: 34 | AT5: 0.41666667 | AU5: =AVERAGEIF($C$2:$AR$2,AU$2,$C5:$AR5) -> 84.833333 | AV5: =AVERAGEIF($C$2:$AR$2,AV$2,$C5:$AR5) -> 77.833333 | AW5: =AVERAGEIF($C$2:$AR$2,AW$2,$C5:$AR5) -> 77.833333 | AX5: =AVERAGEIF($C$2:$AR$2,AX$2,$C5:$AR5) -> 78 | AY5: =AVERAGEIF($C$2:$AR$2,AY$2,$C5:$AR5) -> 66.833333 | AZ5: =AVERAGEIF($C$2:$AR$2,AZ$2,$C5:$AR5) -> 52.833333 | BA5: =AVERAGEIF($C$2:$AR$2,BA$2,$C5:$AR5) -> 33.833333 | BC5: 0.41666667 | BD5: =AU5/AU$33 -> 0.042466211 | BE5: =AV5/AV$33 -> 0.042734261 | BF5: =AW5/AW$33 -> 0.043453987 | BG5: =AX5/AX$33 -> 0.042987049 | BH5: =AY5/AY$33 -> 0.041649356 | BI5: =AZ5/AZ$33 -> 0.044610189 | BJ5: =BA5/BA$33 -> 0.033553719
B6: 0.4375 | C6: 89 | D6: 82 | E6: 81 | F6: 82 | G6: 74 | H6: 53 | I6: 38 | J6: 90 | K6: 83 | L6: 82 | M6: 83 | N6: 75 | O6: 54 | P6: 39 | Q6: 91 | R6: 84 | S6: 83 | T6: 84 | U6: 76 | V6: 55 | W6: 39 | X6: 88 | Y6: 81 | Z6: 80 | AA6: 81 | AB6: 73 | AC6: 52 | AD6: 37 | AE6: 87 | AF6: 80 | AG6: 79 | AH6: 80 | AI6: 72 | AJ6: 51 | AK6: 36 | AL6: 88 | AM6: 82 | AN6: 80 | AO6: 81 | AP6: 73 | AQ6: 52 | AR6: 37 | AT6: 0.4375 | AU6: =AVERAGEIF($C$2:$AR$2,AU$2,$C6:$AR6) -> 88.833333 | AV6: =AVERAGEIF($C$2:$AR$2,AV$2,$C6:$AR6) -> 82 | AW6: =AVERAGEIF($C$2:$AR$2,AW$2,$C6:$AR6) -> 80.833333 | AX6: =AVERAGEIF($C$2:$AR$2,AX$2,$C6:$AR6) -> 81.833333 | AY6: =AVERAGEIF($C$2:$AR$2,AY$2,$C6:$AR6) -> 73.833333 | AZ6: =AVERAGEIF($C$2:$AR$2,AZ$2,$C6:$AR6) -> 52.833333 | BA6: =AVERAGEIF($C$2:$AR$2,BA$2,$C6:$AR6) -> 37.666667 | BC6: 0.4375 | BD6: =AU6/AU$33 -> 0.044468547 | BE6: =AV6/AV$33 -> 0.045021962 | BF6: =AW6/AW$33 -> 0.045128873 | BG6: =AX6/AX$33 -> 0.04509966 | BH6: =AY6/AY$33 -> 0.046011633 | BI6: =AZ6/AZ$33 -> 0.044610189 | BJ6: =BA6/BA$33 -> 0.037355372
B7: 0.45833333 | C7: 92 | D7: 80 | E7: 82 | F7: 77 | G7: 70 | H7: 59 | I7: 43 | J7: 93 | K7: 81 | L7: 83 | M7: 78 | N7: 71 | O7: 60 | P7: 44 | Q7: 94 | R7: 82 | S7: 84 | T7: 79 | U7: 72 | V7: 61 | W7: 44 | X7: 91 | Y7: 79 | Z7: 81 | AA7: 76 | AB7: 69 | AC7: 58 | AD7: 42 | AE7: 90 | AF7: 78 | AG7: 80 | AH7: 75 | AI7: 68 | AJ7: 57 | AK7: 41 | AL7: 91 | AM7: 79 | AN7: 81 | AO7: 76 | AP7: 69 | AQ7: 58 | AR7: 42 | AT7: 0.45833333 | AU7: =AVERAGEIF($C$2:$AR$2,AU$2,$C7:$AR7) -> 91.833333 | AV7: =AVERAGEIF($C$2:$AR$2,AV$2,$C7:$AR7) -> 79.833333 | AW7: =AVERAGEIF($C$2:$AR$2,AW$2,$C7:$AR7) -> 81.833333 | AX7: =AVERAGEIF($C$2:$AR$2,AX$2,$C7:$AR7) -> 76.833333 | AY7: =AVERAGEIF($C$2:$AR$2,AY$2,$C7:$AR7) -> 69.833333 | AZ7: =AVERAGEIF($C$2:$AR$2,AZ$2,$C7:$AR7) -> 58.833333 | BA7: =AVERAGEIF($C$2:$AR$2,BA$2,$C7:$AR7) -> 42.666667 | BC7: 0.45833333 | BD7: =AU7/AU$33 -> 0.045970299 | BE7: =AV7/AV$33 -> 0.043832357 | BF7: =AW7/AW$33 -> 0.045687169 | BG7: =AX7/AX$33 -> 0.04234408 | BH7: =AY7/AY$33 -> 0.043518903 | BI7: =AZ7/AZ$33 -> 0.04967633 | BJ7: =BA7/BA$33 -> 0.04231405
B8: 0.47916667 | C8: 90 | D8: 69 | E8: 76 | F8: 90 | G8: 78 | H8: 57 | I8: 44 | J8: 91 | K8: 70 | L8: 77 | M8: 91 | N8: 79 | O8: 58 | P8: 45 | Q8: 92 | R8: 71 | S8: 78 | T8: 92 | U8: 80 | V8: 59 | W8: 45 | X8: 89 | Y8: 68 | Z8: 75 | AA8: 89 | AB8: 77 | AC8: 56 | AD8: 43 | AE8: 88 | AF8: 67 | AG8: 74 | AH8: 88 | AI8: 76 | AJ8: 55 | AK8: 42 | AL8: 89 | AM8: 69 | AN8: 75 | AO8: 90 | AP8: 77 | AQ8: 56 | AR8: 43 | AT8: 0.47916667 | AU8: =AVERAGEIF($C$2:$AR$2,AU$2,$C8:$AR8) -> 89.833333 | AV8: =AVERAGEIF($C$2:$AR$2,AV$2,$C8:$AR8) -> 69 | AW8: =AVERAGEIF($C$2:$AR$2,AW$2,$C8:$AR8) -> 75.833333 | AX8: =AVERAGEIF($C$2:$AR$2,AX$2,$C8:$AR8) -> 90 | AY8: =AVERAGEIF($C$2:$AR$2,AY$2,$C8:$AR8) -> 77.833333 | AZ8: =AVERAGEIF($C$2:$AR$2,AZ$2,$C8:$AR8) -> 56.833333 | BA8: =AVERAGEIF($C$2:$AR$2,BA$2,$C8:$AR8) -> 43.666667 | BC8: 0.47916667 | BD8: =AU8/AU$33 -> 0.044969131 | BE8: =AV8/AV$33 -> 0.037884334 | BF8: =AW8/AW$33 -> 0.042337396 | BG8: =AX8/AX$33 -> 0.049600441 | BH8: =AY8/AY$33 -> 0.048504362 | BI8: =AZ8/AZ$33 -> 0.047987616 | BJ8: =BA8/BA$33 -> 0.043305785
B9: 0.5 | C9: 87 | D9: 75 | E9: 67 | F9: 75 | G9: 73 | H9: 54 | I9: 46 | J9: 88 | K9: 76 | L9: 68 | M9: 76 | N9: 74 | O9: 55 | P9: 47 | Q9: 89 | R9: 77 | S9: 69 | T9: 77 | U9: 75 | V9: 56 | W9: 47 | X9: 86 | Y9: 74 | Z9: 66 | AA9: 74 | AB9: 72 | AC9: 53 | AD9: 45 | AE9: 85 | AF9: 73 | AG9: 65 | AH9: 73 | AI9: 71 | AJ9: 52 | AK9: 44 | AL9: 86 | AM9: 75 | AN9: 67 | AO9: 74 | AP9: 72 | AQ9: 53 | AR9: 45 | AT9: 0.5 | AU9: =AVERAGEIF($C$2:$AR$2,AU$2,$C9:$AR9) -> 86.833333 | AV9: =AVERAGEIF($C$2:$AR$2,AV$2,$C9:$AR9) -> 75 | AW9: =AVERAGEIF($C$2:$AR$2,AW$2,$C9:$AR9) -> 67 | AX9: =AVERAGEIF($C$2:$AR$2,AX$2,$C9:$AR9) -> 74.833333 | AY9: =AVERAGEIF($C$2:$AR$2,AY$2,$C9:$AR9) -> 72.833333 | AZ9: =AVERAGEIF($C$2:$AR$2,AZ$2,$C9:$AR9) -> 53.833333 | BA9: =AVERAGEIF($C$2:$AR$2,BA$2,$C9:$AR9) -> 45.666667 | BC9: 0.5 | BD9: =AU9/AU$33 -> 0.043467379 | BE9: =AV9/AV$33 -> 0.041178624 | BF9: =AW9/AW$33 -> 0.037405788 | BG9: =AX9/AX$33 -> 0.041241848 | BH9: =AY9/AY$33 -> 0.04538845 | BI9: =AZ9/AZ$33 -> 0.045454545 | BJ9: =BA9/BA$33 -> 0.045289256
B10: 0.52083333 | C10: 79 | D10: 75 | E10: 65 | F10: 74 | G10: 64 | H10: 59 | I10: 38 | J10: 80 | K10: 76 | L10: 66 | M10: 75 | N10: 65 | O10: 60 | P10: 39 | Q10: 81 | R10: 77 | S10: 67 | T10: 76 | U10: 66 | V10: 61 | W10: 39 | X10: 78 | Y10: 74 | Z10: 64 | AA10: 73 | AB10: 63 | AC10: 58 | AD10: 37 | AE10: 77 | AF10: 73 | AG10: 63 | AH10: 72 | AI10: 62 | AJ10: 57 | AK10: 36 | AL10: 78 | AM10: 74 | AN10: 64 | AO10: 73 | AP10: 63 | AQ10: 58 | AR10: 37 | AT10: 0.52083333 | AU10: =AVERAGEIF($C$2:$AR$2,AU$2,$C10:$AR10) -> 78.833333 | AV10: =AVERAGEIF($C$2:$AR$2,AV$2,$C10:$AR10) -> 74.833333 | AW10: =AVERAGEIF($C$2:$AR$2,AW$2,$C10:$AR10) -> 64.833333 | AX10: =AVERAGEIF($C$2:$AR$2,AX$2,$C10:$AR10) -> 73.833333 | AY10: =AVERAGEIF($C$2:$AR$2,AY$2,$C10:$AR10) -> 63.833333 | AZ10: =AVERAGEIF($C$2:$AR$2,AZ$2,$C10:$AR10) -> 58.833333 | BA10: =AVERAGEIF($C$2:$AR$2,BA$2,$C10:$AR10) -> 37.666667 | BC10: 0.52083333 | BD10: =AU10/AU$33 -> 0.039462706 | BE10: =AV10/AV$33 -> 0.041087116 | BF10: =AW10/AW$33 -> 0.036196148 | BG10: =AX10/AX$33 -> 0.040690732 | BH10: =AY10/AY$33 -> 0.039779809 | BI10: =AZ10/AZ$33 -> 0.04967633 | BJ10: =BA10/BA$33 -> 0.037355372
B11: 0.54166667 | C11: 83 | D11: 82 | E11: 70 | F11: 83 | G11: 65 | H11: 51 | I11: 45 | J11: 84 | K11: 83 | L11: 71 | M11: 84 | N11: 66 | O11: 52 | P11: 46 | Q11: 85 | R11: 84 | S11: 72 | T11: 85 | U11: 67 | V11: 53 | W11: 46 | X11: 82 | Y11: 81 | Z11: 69 | AA11: 82 | AB11: 64 | AC11: 50 | AD11: 44 | AE11: 81 | AF11: 80 | AG11: 68 | AH11: 81 | AI11: 63 | AJ11: 49 | AK11: 43 | AL11: 82 | AM11: 81 | AN11: 70 | AO11: 82 | AP11: 64 | AQ11: 50 | AR11: 44 | AT11: 0.54166667 | AU11: =AVERAGEIF($C$2:$AR$2,AU$2,$C11:$AR11) -> 82.833333 | AV11: =AVERAGEIF($C$2:$AR$2,AV$2,$C11:$AR11) -> 81.833333 | AW11: =AVERAGEIF($C$2:$AR$2,AW$2,$C11:$AR11) -> 70 | AX11: =AVERAGEIF($C$2:$AR$2,AX$2,$C11:$AR11) -> 82.833333 | AY11: =AVERAGEIF($C$2:$AR$2,AY$2,$C11:$AR11) -> 64.833333 | AZ11: =AVERAGEIF($C$2:$AR$2,AZ$2,$C11:$AR11) -> 50.833333 | BA11: =AVERAGEIF($C$2:$AR$2,BA$2,$C11:$AR11) -> 44.666667 | BC11: 0.54166667 | BD11: =AU11/AU$33 -> 0.041465043 | BE11: =AV11/AV$33 -> 0.044930454 | BF11: =AW11/AW$33 -> 0.039080674 | BG11: =AX11/AX$33 -> 0.045650776 | BH11: =AY11/AY$33 -> 0.040402991 | BI11: =AZ11/AZ$33 -> 0.042921475 | BJ11: =BA11/BA$33 -> 0.044297521
B12: 0.5625 | C12: 84 | D12: 83 | E12: 78 | F12: 71 | G12: 72 | H12: 45 | I12: 42 | J12: 85 | K12: 84 | L12: 79 | M12: 72 | N12: 73 | O12: 46 | P12: 43 | Q12: 86 | R12: 85 | S12: 80 | T12: 73 | U12: 74 | V12: 47 | W12: 43 | X12: 83 | Y12: 82 | Z12: 77 | AA12: 70 | AB12: 71 | AC12: 44 | AD12: 41 | AE12: 82 | AF12: 81 | AG12: 76 | AH12: 69 | AI12: 70 | AJ12: 43 | AK12: 40 | AL12: 83 | AM12: 82 | AN12: 77 | AO12: 71 | AP12: 71 | AQ12: 44 | AR12: 41 | AT12: 0.5625 | AU12: =AVERAGEIF($C$2:$AR$2,AU$2,$C12:$AR12) -> 83.833333 | AV12: =AVERAGEIF($C$2:$AR$2,AV$2,$C12:$AR12) -> 82.833333 | AW12: =AVERAGEIF($C$2:$AR$2,AW$2,$C12:$AR12) -> 77.833333 | AX12: =AVERAGEIF($C$2:$AR$2,AX$2,$C12:$AR12) -> 71 | AY12: =AVERAGEIF($C$2:$AR$2,AY$2,$C12:$AR12) -> 71.833333 | AZ12: =AVERAGEIF($C$2:$AR$2,AZ$2,$C12:$AR12) -> 44.833333 | BA12: =AVERAGEIF($C$2:$AR$2,BA$2,$C12:$AR12) -> 41.666667 | BC12: 0.5625 | BD12: =AU12/AU$33 -> 0.041965627 | BE12: =AV12/AV$33 -> 0.045479502 | BF12: =AW12/AW$33 -> 0.043453987 | BG12: =AX12/AX$33 -> 0.039129237 | BH12: =AY12/AY$33 -> 0.044765268 | BI12: =AZ12/AZ$33 -> 0.037855334 | BJ12: =BA12/BA$33 -> 0.041322314
B13: 0.58333333 | C13: 89 | D13: 77 | E13: 84 | F13: 78 | G13: 72 | H13: 42 | I13: 42 | J13: 90 | K13: 78 | L13: 85 | M13: 79 | N13: 73 | O13: 43 | P13: 43 | Q13: 91 | R13: 79 | S13: 86 | T13: 80 | U13: 74 | V13: 43 | W13: 43 | X13: 88 | Y13: 76 | Z13: 83 | AA13: 77 | AB13: 71 | AC13: 41 | AD13: 41 | AE13: 87 | AF13: 75 | AG13: 82 | AH13: 76 | AI13: 70 | AJ13: 40 | AK13: 40 | AL13: 88 | AM13: 76 | AN13: 83 | AO13: 77 | AP13: 71 | AQ13: 41 | AR13: 41 | AT13: 0.58333333 | AU13: =AVERAGEIF($C$2:$AR$2,AU$2,$C13:$AR13) -> 88.833333 | AV13: =AVERAGEIF($C$2:$AR$2,AV$2,$C13:$AR13) -> 76.833333 | AW13: =AVERAGEIF($C$2:$AR$2,AW$2,$C13:$AR13) -> 83.833333 | AX13: =AVERAGEIF($C$2:$AR$2,AX$2,$C13:$AR13) -> 77.833333 | AY13: =AVERAGEIF($C$2:$AR$2,AY$2,$C13:$AR13) -> 71.833333 | AZ13: =AVERAGEIF($C$2:$AR$2,AZ$2,$C13:$AR13) -> 41.666667 | BA13: =AVERAGEIF($C$2:$AR$2,BA$2,$C13:$AR13) -> 41.666667 | BC13: 0.58333333 | BD13: =AU13/AU$33 -> 0.044468547 | BE13: =AV13/AV$33 -> 0.042185212 | BF13: =AW13/AW$33 -> 0.046803759 | BG13: =AX13/AX$33 -> 0.042895196 | BH13: =AY13/AY$33 -> 0.044765268 | BI13: =AZ13/AZ$33 -> 0.035181537 | BJ13: =BA13/BA$33 -> 0.041322314
B14: 0.60416667 | C14: 103 | D14: 82 | E14: 87 | F14: 80 | G14: 72 | H14: 52 | I14: 48 | J14: 104 | K14: 83 | L14: 88 | M14: 81 | N14: 73 | O14: 53 | P14: 49 | Q14: 105 | R14: 84 | S14: 89 | T14: 82 | U14: 74 | V14: 54 | W14: 49 | X14: 102 | Y14: 81 | Z14: 86 | AA14: 79 | AB14: 71 | AC14: 51 | AD14: 47 | AE14: 101 | AF14: 80 | AG14: 85 | AH14: 78 | AI14: 70 | AJ14: 50 | AK14: 46 | AL14: 102 | AM14: 81 | AN14: 86 | AO14: 79 | AP14: 71 | AQ14: 51 | AR14: 47 | AT14: 0.60416667 | AU14: =AVERAGEIF($C$2:$AR$2,AU$2,$C14:$AR14) -> 102.83333 | AV14: =AVERAGEIF($C$2:$AR$2,AV$2,$C14:$AR14) -> 81.833333 | AW14: =AVERAGEIF($C$2:$AR$2,AW$2,$C14:$AR14) -> 86.833333 | AX14: =AVERAGEIF($C$2:$AR$2,AX$2,$C14:$AR14) -> 79.833333 | AY14: =AVERAGEIF($C$2:$AR$2,AY$2,$C14:$AR14) -> 71.833333 | AZ14: =AVERAGEIF($C$2:$AR$2,AZ$2,$C14:$AR14) -> 51.833333 | BA14: =AVERAGEIF($C$2:$AR$2,BA$2,$C14:$AR14) -> 47.666667 | BC14: 0.60416667 | BD14: =AU14/AU$33 -> 0.051476723 | BE14: =AV14/AV$33 -> 0.044930454 | BF14: =AW14/AW$33 -> 0.048478645 | BG14: =AX14/AX$33 -> 0.043997428 | BH14: =AY14/AY$33 -> 0.044765268 | BI14: =AZ14/AZ$33 -> 0.043765832 | BJ14: =BA14/BA$33 -> 0.047272727
... B32: 0.97916667 | C32: 18 | D32: 20 | E32: 17 | F32: 24 | G32: 24 | H32: 20 | I32: 12 | J32: 19 | K32: 21 | L32: 18 | M32: 25 | N32: 25 | O32: 21 | P32: 13 | Q32: 19 | R32: 21 | S32: 18 | T32: 25 | U32: 25 | V32: 21 | W32: 13 | X32: 17 | Y32: 19 | Z32: 16 | AA32: 23 | AB32: 23 | AC32: 19 | AD32: 11 | AE32: 16 | AF32: 18 | AG32: 15 | AH32: 22 | AI32: 22 | AJ32: 18 | AK32: 10 | AL32: 17 | AM32: 19 | AN32: 16 | AO32: 23 | AP32: 23 | AQ32: 19 | AR32: 11 | AT32: 0.97916667 | AU32: =AVERAGEIF($C$2:$AR$2,AU$2,$C32:$AR32) -> 17.666667 | AV32: =AVERAGEIF($C$2:$AR$2,AV$2,$C32:$AR32) -> 19.666667 | AW32: =AVERAGEIF($C$2:$AR$2,AW$2,$C32:$AR32) -> 16.666667 | AX32: =AVERAGEIF($C$2:$AR$2,AX$2,$C32:$AR32) -> 23.666667 | AY32: =AVERAGEIF($C$2:$AR$2,AY$2,$C32:$AR32) -> 23.666667 | AZ32: =AVERAGEIF($C$2:$AR$2,AZ$2,$C32:$AR32) -> 19.666667 | BA32: =AVERAGEIF($C$2:$AR$2,BA$2,$C32:$AR32) -> 11.666667 | BC32: 0.97916667 | BD32: =AU32/AU$33 -> 0.0088436509 | BE32: =AV32/AV$33 -> 0.01079795 | BF32: =AW32/AW$33 -> 0.0093049223 | BG32: =AX32/AX$33 -> 0.013043079 | BH32: =AY32/AY$33 -> 0.01474865 | BI32: =AZ32/AZ$33 -> 0.016605685 | BJ32: =BA32/BA$33 -> 0.011570248
B33: Total | C33: 2004 | D33: 1825 | E33: 1797 | F33: 1811 | G33: 1612 | H33: 1190 | I33: 1014 | J33: 2034 | K33: 1846 | L33: 1819 | M33: 1839 | N33: 1636 | O33: 1207 | P33: 1029 | Q33: 2058 | R33: 1872 | S33: 1846 | T33: 1866 | U33: 1663 | V33: 1229 | W33: 1042 | X33: 1984 | Y33: 1807 | Z33: 1779 | AA33: 1793 | AB33: 1596 | AC33: 1178 | AD33: 1004 | AE33: 1968 | AF33: 1790 | AG33: 1762 | AH33: 1777 | AI33: 1580 | AJ33: 1167 | AK33: 995 | AL33: 1994 | AM33: 1816 | AN33: 1788 | AO33: 1802 | AP33: 1603 | AQ33: 1184 | AR33: 1009 | AT33: Total | AU33: =SUM(AU$3:AU$32) -> 1997.6667 | AV33: =SUM(AV$3:AV$32) -> 1821.3333 | AW33: =SUM(AW$3:AW$32) -> 1791.1667 | AX33: =SUM(AX$3:AX$32) -> 1814.5 | AY33: =SUM(AY$3:AY$32) -> 1604.6667 | AZ33: =SUM(AZ$3:AZ$32) -> 1184.3333 | BA33: =SUM(BA$3:BA$32) -> 1008.3333 | BC33: Total | BD33: =SUM(BD3:BD32) -> 1 | BE33: =SUM(BE3:BE32) -> 1 | BF33: =SUM(BF3:BF32) -> 1 | BG33: =SUM(BG3:BG32) -> 1 | BH33: =SUM(BH3:BH32) -> 1 | BI33: =SUM(BI3:BI32) -> 1 | BJ33: =SUM(BJ3:BJ32) -> 1
AT34: percentage per week | AU34: =AU$33/SUM($AU$33:$BA$33) -> 0.17801343 | AV34: =AV$33/SUM($AU$33:$BA$33) -> 0.16230024 | AW34: =AW$33/SUM($AU$33:$BA$33) -> 0.15961207 | AX34: =AX$33/SUM($AU$33:$BA$33) -> 0.16169132 | AY34: =AY$33/SUM($AU$33:$BA$33) -> 0.14299293 | AZ34: =AZ$33/SUM($AU$33:$BA$33) -> 0.10553674 | BA34: =BA$33/SUM($AU$33:$BA$33) -> 0.089853264

Sheet Schedule Validation
U2: Calls | V2: AHT | W2: Occ
B3: Call Arrival Pattern | K3: Distribution | T3: Forecast | U3: 6000 | V3: 300 | W3: 0.8 | AC3: Requirment | AL3: Schedule | AU3: Schedule Post Shrinkage | BD3: Call Capacity | BM3: Staffing Over/Under | BV3: Capacity Over/Under
B4: Intervals | C4: 45928 | D4: 45929 | E4: 45930 | F4: 45931 | G4: 45932 | H4: 45933 | I4: 45934 | K4: Intervals | L4: 45928 | M4: 45929 | N4: 45930 | O4: 45931 | P4: 45932 | Q4: 45933 | R4: 45934 | T4: Intervals | U4: 45928 | V4: 45929 | W4: 45930 | X4: 45931 | Y4: 45932 | Z4: 45933 | AA4: 45934 | AC4: Intervals | AD4: 45928 | AE4: 45929 | AF4: 45930 | AG4: 45931 | AH4: 45932 | AI4: 45933 | AJ4: 45934 | AL4: Intervals | AM4: 45928 | AN4: 45929 | AO4: 45930 | AP4: 45931 | AQ4: 45932 | AR4: 45933 | AS4: 45934 | AU4: Intervals | AV4: 45928 | AW4: 45929 | AX4: 45930 | AY4: 45931 | AZ4: 45932 | BA4: 45933 | BB4: 45934 | BD4: Intervals | BE4: 45928 | BF4: 45929 | BG4: 45930 | BH4: 45931 | BI4: 45932 | BJ4: 45933 | BK4: 45934 | BM4: Intervals | BN4: 45928 | BO4: 45929 | BP4: 45930 | BQ4: 45931 | BR4: 45932 | BS4: 45933 | BT4: 45934 | BV4: Intervals | BW4: 45928 | BX4: 45929 | BY4: 45930 | BZ4: 45931 | CA4: 45932 | CB4: 45933 | CC4: 45934
C5: Sun | D5: Mon | E5: Tue | F5: Wed | G5: Thu | H5: Fri | I5: Sat | L5: Sun | M5: Mon | N5: Tue | O5: Wed | P5: Thu | Q5: Fri | R5: Sat | U5: Sun | V5: Mon | W5: Tue | X5: Wed | Y5: Thu | Z5: Fri | AA5: Sat | AD5: Sun | AE5: Mon | AF5: Tue | AG5: Wed | AH5: Thu | AI5: Fri | AJ5: Sat | AM5: Sun | AN5: Mon | AO5: Tue | AP5: Wed | AQ5: Thu | AR5: Fri | AS5: Sat | AV5: Sun | AW5: Mon | AX5: Tue | AY5: Wed | AZ5: Thu | BA5: Fri | BB5: Sat | BE5: Sun | BF5: Mon | BG5: Tue | BH5: Wed | BI5: Thu | BJ5: Fri | BK5: Sat | BN5: Sun | BO5: Mon | BP5: Tue | BQ5: Wed | BR5: Thu | BS5: Fri | BT5: Sat | BW5: Sun | BX5: Mon | BY5: Tue | BZ5: Wed | CA5: Thu | CB5: Fri | CC5: Sat
B6: 0.375 | C6: 69.833333 | D6: 56 | E6: 62.833333 | F6: 57 | G6: 49.833333 | H6: 35.666667 | I6: 29.833333 | K6: 0.375 | L6: 0.03495745 | M6: 0.030746706 | N6: 0.035079557 | O6: 0.031413613 | P6: 0.031055256 | Q6: 0.030115395 | R6: 0.029586777 | T6: 0.375 | U6: =$U$3*C$37*L6 -> 37.337373 | V6: =$U$3*D$37*M6 -> 29.941187 | W6: =$U$3*E$37*N6 -> 33.594725 | X6: =$U$3*F$37*O6 -> 30.475851 | Y6: =$U$3*G$37*P6 -> 26.644092 | Z6: =$U$3*H$37*Q6 -> 19.069685 | AA6: =$U$3*I$37*R6 -> 15.950811 | AC6: 0.375 | AD6: =(U6*$V$3)/(1800*$W$3) -> 7.7786194 | AE6: =(V6*$V$3)/(1800*$W$3) -> 6.2377473 | AF6: =(W6*$V$3)/(1800*$W$3) -> 6.998901 | AG6: =(X6*$V$3)/(1800*$W$3) -> 6.3491356 | AH6: =(Y6*$V$3)/(1800*$W$3) -> 5.5508525 | AI6: =(Z6*$V$3)/(1800*$W$3) -> 3.9728509 | AJ6: =(AA6*$V$3)/(1800*$W$3) -> 3.3230856 | AL6: 0.375 | AM6: =Roster!G$55 -> 24 | AN6: =Roster!H$55 -> 19 | AO6: =Roster!I$55 -> 19 | AP6: =Roster!J$55 -> 15 | AQ6: =Roster!K$55 -> 15 | AR6: =Roster!L$55 -> 15 | AS6: =Roster!M$55 -> 15 | AU6: 0.375 | AV6: =AM6*(1-32%) -> 16.32 | AW6: =AN6*(1-32%) -> 12.92 | AX6: =AO6*(1-32%) -> 12.92 | AY6: =AP6*(1-32%) -> 10.2 | AZ6: =AQ6*(1-32%) -> 10.2 | BA6: =AR6*(1-32%) -> 10.2 | BB6: =AS6*(1-32%) -> 10.2 | BD6: 0.375 | BE6: =AV6*1800*$W$3/300 -> 78.336 | BF6: =AW6*1800*$W$3/300 -> 62.016 | BG6: =AX6*1800*$W$3/300 -> 62.016 | BH6: =AY6*1800*$W$3/300 -> 48.96 | BI6: =AZ6*1800*$W$3/300 -> 48.96 | BJ6: =BA6*1800*$W$3/300 -> 48.96 | BK6: =BB6*1800*$W$3/300 -> 48.96 | BM6: 0.375 | BN6: =AV6-AD6 -> 8.5413806 | BO6: =AW6-AE6 -> 6.6822527 | BP6: =AX6-AF6 -> 5.921099 | BQ6: =AY6-AG6 -> 3.8508644 | BR6: =AZ6-AH6 -> 4.6491475 | BS6: =BA6-AI6 -> 6.2271491 | BT6: =BB6-AJ6 -> 6.8769144 | BV6: 0.375 | BW6: =BE6-U6 -> 40.998627 | BX6: =BF6-V6 -> 32.074813 | BY6: =BG6-W6 -> 28.421275 | BZ6: =BH6-X6 -> 18.484149 | CA6: =BI6-Y6 -> 22.315908 | CB6: =BJ6-Z6 -> 29.890315 | CC6: =BK6-AA6 -> 33.009189
B7: 0.39583333 | C7: 79.833333 | D7: 76.833333 | E7: 73 | F7: 71 | G7: 60.833333 | H7: 44.833333 | I7: 32.666667 | K7: 0.39583333 | L7: 0.039963291 | M7: 0.042185212 | N7: 0.04075556 | O7: 0.039129237 | P7: 0.037910262 | Q7: 0.037855334 | R7: 0.032396694 | T7: 0.39583333 | U7: =$U$3*C$37*L7 -> 42.684014 | V7: =$U$3*D$37*M7 -> 41.080021 | W7: =$U$3*E$37*N7 -> 39.030476 | X7: =$U$3*F$37*O7 -> 37.961148 | Y7: =$U$3*G$37*P7 -> 32.525397 | Z7: =$U$3*H$37*Q7 -> 23.970772 | AA7: =$U$3*I$37*R7 -> 17.465692 | AC7: 0.39583333 | AD7: =(U7*$V$3)/(1800*$W$3) -> 8.8925028 | AE7: =(V7*$V$3)/(1800*$W$3) -> 8.5583378 | AF7: =(W7*$V$3)/(1800*$W$3) -> 8.1313491 | AG7: =(X7*$V$3)/(1800*$W$3) -> 7.9085724 | AH7: =(Y7*$V$3)/(1800*$W$3) -> 6.7761243 | AI7: =(Z7*$V$3)/(1800*$W$3) -> 4.9939108 | AJ7: =(AA7*$V$3)/(1800*$W$3) -> 3.6386859 | AL7: 0.39583333 | AM7: =Roster!G$55 -> 24 | AN7: =Roster!H$55 -> 19 | AO7: =Roster!I$55 -> 19 | AP7: =Roster!J$55 -> 15 | AQ7: =Roster!K$55 -> 15 | AR7: =Roster!L$55 -> 15 | AS7: =Roster!M$55 -> 15 | AU7: 0.39583333 | AV7: =AM7*(1-32%) -> 16.32 | AW7: =AN7*(1-32%) -> 12.92 | AX7: =AO7*(1-32%) -> 12.92 | AY7: =AP7*(1-32%) -> 10.2 | AZ7: =AQ7*(1-32%) -> 10.2 | BA7: =AR7*(1-32%) -> 10.2 | BB7: =AS7*(1-32%) -> 10.2 | BD7: 0.39583333 | BE7: =AV7*1800*$W$3/300 -> 78.336 | BF7: =AW7*1800*$W$3/300 -> 62.016 | BG7: =AX7*1800*$W$3/300 -> 62.016 | BH7: =AY7*1800*$W$3/300 -> 48.96 | BI7: =AZ7*1800*$W$3/300 -> 48.96 | BJ7: =BA7*1800*$W$3/300 -> 48.96 | BK7: =BB7*1800*$W$3/300 -> 48.96 | BM7: 0.39583333 | BN7: =AV7-AD7 -> 7.4274972 | BO7: =AW7-AE7 -> 4.3616622 | BP7: =AX7-AF7 -> 4.7886509 | BQ7: =AY7-AG7 -> 2.2914276 | BR7: =AZ7-AH7 -> 3.4238757 | BS7: =BA7-AI7 -> 5.2060892 | BT7: =BB7-AJ7 -> 6.5613141 | BV7: 0.39583333 | BW7: =BE7-U7 -> 35.651986 | BX7: =BF7-V7 -> 20.935979 | BY7: =BG7-W7 -> 22.985524 | BZ7: =BH7-X7 -> 10.998852 | CA7: =BI7-Y7 -> 16.434603 | CB7: =BJ7-Z7 -> 24.989228 | CC7: =BK7-AA7 -> 31.494308
B8: 0.41666667 | C8: 84.833333 | D8: 77.833333 | E8: 77.833333 | F8: 78 | G8: 66.833333 | H8: 52.833333 | I8: 33.833333 | K8: 0.41666667 | L8: 0.042466211 | M8: 0.042734261 | N8: 0.043453987 | O8: 0.042987049 | P8: 0.041649356 | Q8: 0.044610189 | R8: 0.033553719 | T8: 0.41666667 | U8: =$U$3*C$37*L8 -> 45.357334 | V8: =$U$3*D$37*M8 -> 41.614685 | W8: =$U$3*E$37*N8 -> 41.614685 | X8: =$U$3*F$37*O8 -> 41.703796 | Y8: =$U$3*G$37*P8 -> 35.733381 | Z8: =$U$3*H$37*Q8 -> 28.248084 | AA8: =$U$3*I$37*R8 -> 18.089467 | AC8: 0.41666667 | AD8: =(U8*$V$3)/(1800*$W$3) -> 9.4494445 | AE8: =(V8*$V$3)/(1800*$W$3) -> 8.6697261 | AF8: =(W8*$V$3)/(1800*$W$3) -> 8.6697261 | AG8: =(X8*$V$3)/(1800*$W$3) -> 8.6882909 | AH8: =(Y8*$V$3)/(1800*$W$3) -> 7.4444543 | AI8: =(Z8*$V$3)/(1800*$W$3) -> 5.8850175 | AJ8: =(AA8*$V$3)/(1800*$W$3) -> 3.768639 | AL8: 0.41666667 | AM8: =Roster!G$55+Roster!G$56 -> 24 | AN8: =Roster!H$55+Roster!H$56 -> 19 | AO8: =Roster!I$55+Roster!I$56 -> 19 | AP8: =Roster!J$55+Roster!J$56 -> 15 | AQ8: =Roster!K$55+Roster!K$56 -> 15 | AR8: =Roster!L$55+Roster!L$56 -> 15 | AS8: =Roster!M$55+Roster!M$56 -> 15 | AU8: 0.41666667 | AV8: =AM8*(1-32%) -> 16.32 | AW8: =AN8*(1-32%) -> 12.92 | AX8: =AO8*(1-32%) -> 12.92 | AY8: =AP8*(1-32%) -> 10.2 | AZ8: =AQ8*(1-32%) -> 10.2 | BA8: =AR8*(1-32%) -> 10.2 | BB8: =AS8*(1-32%) -> 10.2 | BD8: 0.41666667 | BE8: =AV8*1800*$W$3/300 -> 78.336 | BF8: =AW8*1800*$W$3/300 -> 62.016 | BG8: =AX8*1800*$W$3/300 -> 62.016 | BH8: =AY8*1800*$W$3/300 -> 48.96 | BI8: =AZ8*1800*$W$3/300 -> 48.96 | BJ8: =BA8*1800*$W$3/300 -> 48.96 | BK8: =BB8*1800*$W$3/300 -> 48.96 | BM8: 0.41666667 | BN8: =AV8-AD8 -> 6.8705555 | BO8: =AW8-AE8 -> 4.2502739 | BP8: =AX8-AF8 -> 4.2502739 | BQ8: =AY8-AG8 -> 1.5117091 | BR8: =AZ8-AH8 -> 2.7555457 | BS8: =BA8-AI8 -> 4.3149825 | BT8: =BB8-AJ8 -> 6.431361 | BV8: 0.41666667 | BW8: =BE8-U8 -> 32.978666 | BX8: =BF8-V8 -> 20.401315 | BY8: =BG8-W8 -> 20.401315 | BZ8: =BH8-X8 -> 7.2562039 | CA8: =BI8-Y8 -> 13.226619 | CB8: =BJ8-Z8 -> 20.711916 | CC8: =BK8-AA8 -> 30.870533
B9: 0.4375 | C9: 88.833333 | D9: 82 | E9: 80.833333 | F9: 81.833333 | G9: 73.833333 | H9: 52.833333 | I9: 37.666667 | K9: 0.4375 | L9: 0.044468547 | M9: 0.045021962 | N9: 0.045128873 | O9: 0.04509966 | P9: 0.046011633 | Q9: 0.044610189 | R9: 0.037355372 | T9: 0.4375 | U9: =$U$3*C$37*L9 -> 47.49599 | V9: =$U$3*D$37*M9 -> 43.842452 | W9: =$U$3*E$37*N9 -> 43.218678 | X9: =$U$3*F$37*O9 -> 43.753342 | Y9: =$U$3*G$37*P9 -> 39.476029 | Z9: =$U$3*H$37*Q9 -> 28.248084 | AA9: =$U$3*I$37*R9 -> 20.139013 | AC9: 0.4375 | AD9: =(U9*$V$3)/(1800*$W$3) -> 9.8949979 | AE9: =(V9*$V$3)/(1800*$W$3) -> 9.1338442 | AF9: =(W9*$V$3)/(1800*$W$3) -> 9.0038912 | AG9: =(X9*$V$3)/(1800*$W$3) -> 9.1152795 | AH9: =(Y9*$V$3)/(1800*$W$3) -> 8.2241728 | AI9: =(Z9*$V$3)/(1800*$W$3) -> 5.8850175 | AJ9: =(AA9*$V$3)/(1800*$W$3) -> 4.1956276 | AL9: 0.4375 | AM9: =Roster!G$55+Roster!G$56 -> 24 | AN9: =Roster!H$55+Roster!H$56 -> 19 | AO9: =Roster!I$55+Roster!I$56 -> 19 | AP9: =Roster!J$55+Roster!J$56 -> 15 | AQ9: =Roster!K$55+Roster!K$56 -> 15 | AR9: =Roster!L$55+Roster!L$56 -> 15 | AS9: =Roster!M$55+Roster!M$56 -> 15 | AU9: 0.4375 | AV9: =AM9*(1-32%) -> 16.32 | AW9: =AN9*(1-32%) -> 12.92 | AX9: =AO9*(1-32%) -> 12.92 | AY9: =AP9*(1-32%) -> 10.2 | AZ9: =AQ9*(1-32%) -> 10.2 | BA9: =AR9*(1-32%) -> 10.2 | BB9: =AS9*(1-32%) -> 10.2 | BD9: 0.4375 | BE9: =AV9*1800*$W$3/300 -> 78.336 | BF9: =AW9*1800*$W$3/300 -> 62.016 | BG9: =AX9*1800*$W$3/300 -> 62.016 | BH9: =AY9*1800*$W$3/300 -> 48.96 | BI9: =AZ9*1800*$W$3/300 -> 48.96 | BJ9: =BA9*1800*$W$3/300 -> 48.96 | BK9: =BB9*1800*$W$3/300 -> 48.96 | BM9: 0.4375 | BN9: =AV9-AD9 -> 6.4250021 | BO9: =AW9-AE9 -> 3.7861558 | BP9: =AX9-AF9 -> 3.9161088 | BQ9: =AY9-AG9 -> 1.0847205 | BR9: =AZ9-AH9 -> 1.9758272 | BS9: =BA9-AI9 -> 4.3149825 | BT9: =BB9-AJ9 -> 6.0043724 | BV9: 0.4375 | BW9: =BE9-U9 -> 30.84001 | BX9: =BF9-V9 -> 18.173548 | BY9: =BG9-W9 -> 18.797322 | BZ9: =BH9-X9 -> 5.2066583 | CA9: =BI9-Y9 -> 9.4839708 | CB9: =BJ9-Z9 -> 20.711916 | CC9: =BK9-AA9 -> 28.820987
B10: 0.45833333 | C10: 91.833333 | D10: 79.833333 | E10: 81.833333 | F10: 76.833333 | G10: 69.833333 | H10: 58.833333 | I10: 42.666667 | K10: 0.45833333 | L10: 0.045970299 | M10: 0.043832357 | N10: 0.045687169 | O10: 0.04234408 | P10: 0.043518903 | Q10: 0.04967633 | R10: 0.04231405 | T10: 0.45833333 | U10: =$U$3*C$37*L10 -> 49.099982 | V10: =$U$3*D$37*M10 -> 42.684014 | W10: =$U$3*E$37*N10 -> 43.753342 | X10: =$U$3*F$37*O10 -> 41.080021 | Y10: =$U$3*G$37*P10 -> 37.337373 | Z10: =$U$3*H$37*Q10 -> 31.456068 | AA10: =$U$3*I$37*R10 -> 22.812333 | AC10: 0.45833333 | AD10: =(U10*$V$3)/(1800*$W$3) -> 10.229163 | AE10: =(V10*$V$3)/(1800*$W$3) -> 8.8925028 | AF10: =(W10*$V$3)/(1800*$W$3) -> 9.1152795 | AG10: =(X10*$V$3)/(1800*$W$3) -> 8.5583378 | AH10: =(Y10*$V$3)/(1800*$W$3) -> 7.7786194 | AI10: =(Z10*$V$3)/(1800*$W$3) -> 6.5533476 | AJ10: =(AA10*$V$3)/(1800*$W$3) -> 4.7525694 | AL10: 0.45833333 | AM10: =Roster!G$55+Roster!G$56 -> 24 | AN10: =Roster!H$55+Roster!H$56 -> 19 | AO10: =Roster!I$55+Roster!I$56 -> 19 | AP10: =Roster!J$55+Roster!J$56 -> 15 | AQ10: =Roster!K$55+Roster!K$56 -> 15 | AR10: =Roster!L$55+Roster!L$56 -> 15 | AS10: =Roster!M$55+Roster!M$56 -> 15 | AU10: 0.45833333 | AV10: =AM10*(1-32%) -> 16.32 | AW10: =AN10*(1-32%) -> 12.92 | AX10: =AO10*(1-32%) -> 12.92 | AY10: =AP10*(1-32%) -> 10.2 | AZ10: =AQ10*(1-32%) -> 10.2 | BA10: =AR10*(1-32%) -> 10.2 | BB10: =AS10*(1-32%) -> 10.2 | BD10: 0.45833333 | BE10: =AV10*1800*$W$3/300 -> 78.336 | BF10: =AW10*1800*$W$3/300 -> 62.016 | BG10: =AX10*1800*$W$3/300 -> 62.016 | BH10: =AY10*1800*$W$3/300 -> 48.96 | BI10: =AZ10*1800*$W$3/300 -> 48.96 | BJ10: =BA10*1800*$W$3/300 -> 48.96 | BK10: =BB10*1800*$W$3/300 -> 48.96 | BM10: 0.45833333 | BN10: =AV10-AD10 -> 6.090837 | BO10: =AW10-AE10 -> 4.0274972 | BP10: =AX10-AF10 -> 3.8047205 | BQ10: =AY10-AG10 -> 1.6416622 | BR10: =AZ10-AH10 -> 2.4213806 | BS10: =BA10-AI10 -> 3.6466524 | BT10: =BB10-AJ10 -> 5.4474306 | BV10: 0.45833333 | BW10: =BE10-U10 -> 29.236018 | BX10: =BF10-V10 -> 19.331986 | BY10: =BG10-W10 -> 18.262658 | BZ10: =BH10-X10 -> 7.8799786 | CA10: =BI10-Y10 -> 11.622627 | CB10: =BJ10-Z10 -> 17.503932 | CC10: =BK10-AA10 -> 26.147667
B11: 0.47916667 | C11: 89.833333 | D11: 69 | E11: 75.833333 | F11: 90 | G11: 77.833333 | H11: 56.833333 | I11: 43.666667 | K11: 0.47916667 | L11: 0.044969131 | M11: 0.037884334 | N11: 0.042337396 | O11: 0.049600441 | P11: 0.048504362 | Q11: 0.047987616 | R11: 0.043305785 | T11: 0.47916667 | U11: =$U$3*C$37*L11 -> 48.030654 | V11: =$U$3*D$37*M11 -> 36.89182 | W11: =$U$3*E$37*N11 -> 40.545357 | X11: =$U$3*F$37*O11 -> 48.119765 | Y11: =$U$3*G$37*P11 -> 41.614685 | Z11: =$U$3*H$37*Q11 -> 30.38674 | AA11: =$U$3*I$37*R11 -> 23.346997 | AC11: 0.47916667 | AD11: =(U11*$V$3)/(1800*$W$3) -> 10.006386 | AE11: =(V11*$V$3)/(1800*$W$3) -> 7.6857958 | AF11: =(W11*$V$3)/(1800*$W$3) -> 8.4469494 | AG11: =(X11*$V$3)/(1800*$W$3) -> 10.024951 | AH11: =(Y11*$V$3)/(1800*$W$3) -> 8.6697261 | AI11: =(Z11*$V$3)/(1800*$W$3) -> 6.3305709 | AJ11: =(AA11*$V$3)/(1800*$W$3) -> 4.8639577 | AL11: 0.47916667 | AM11: =Roster!G$55+Roster!G$56 -> 24 | AN11: =Roster!H$55+Roster!H$56 -> 19 | AO11: =Roster!I$55+Roster!I$56 -> 19 | AP11: =Roster!J$55+Roster!J$56 -> 15 | AQ11: =Roster!K$55+Roster!K$56 -> 15 | AR11: =Roster!L$55+Roster!L$56 -> 15 | AS11: =Roster!M$55+Roster!M$56 -> 15 | AU11: 0.47916667 | AV11: =AM11*(1-32%) -> 16.32 | AW11: =AN11*(1-32%) -> 12.92 | AX11: =AO11*(1-32%) -> 12.92 | AY11: =AP11*(1-32%) -> 10.2 | AZ11: =AQ11*(1-32%) -> 10.2 | BA11: =AR11*(1-32%) -> 10.2 | BB11: =AS11*(1-32%) -> 10.2 | BD11: 0.47916667 | BE11: =AV11*1800*$W$3/300 -> 78.336 | BF11: =AW11*1800*$W$3/300 -> 62.016 | BG11: =AX11*1800*$W$3/300 -> 62.016 | BH11: =AY11*1800*$W$3/300 -> 48.96 | BI11: =AZ11*1800*$W$3/300 -> 48.96 | BJ11: =BA11*1800*$W$3/300 -> 48.96 | BK11: =BB11*1800*$W$3/300 -> 48.96 | BM11: 0.47916667 | BN11: =AV11-AD11 -> 6.3136137 | BO11: =AW11-AE11 -> 5.2342042 | BP11: =AX11-AF11 -> 4.4730506 | BQ11: =AY11-AG11 -> 0.17504901 | BR11: =AZ11-AH11 -> 1.5302739 | BS11: =BA11-AI11 -> 3.8694291 | BT11: =BB11-AJ11 -> 5.3360423 | BV11: 0.47916667 | BW11: =BE11-U11 -> 30.305346 | BX11: =BF11-V11 -> 25.12418 | BY11: =BG11-W11 -> 21.470643 | BZ11: =BH11-X11 -> 0.84023525 | CA11: =BI11-Y11 -> 7.3453146 | CB11: =BJ11-Z11 -> 18.57326 | CC11: =BK11-AA11 -> 25.613003
B12: 0.5 | C12: 86.833333 | D12: 75 | E12: 67 | F12: 74.833333 | G12: 72.833333 | H12: 53.833333 | I12: 45.666667 | K12: 0.5 | L12: 0.043467379 | M12: 0.041178624 | N12: 0.037405788 | O12: 0.041241848 | P12: 0.04538845 | Q12: 0.045454545 | R12: 0.045289256 | T12: 0.5 | U12: =$U$3*C$37*L12 -> 46.426662 | V12: =$U$3*D$37*M12 -> 40.099804 | W12: =$U$3*E$37*N12 -> 35.822492 | X12: =$U$3*F$37*O12 -> 40.010693 | Y12: =$U$3*G$37*P12 -> 38.941365 | Z12: =$U$3*H$37*Q12 -> 28.782748 | AA12: =$U$3*I$37*R12 -> 24.416325 | AC12: 0.5 | AD12: =(U12*$V$3)/(1800*$W$3) -> 9.6722212 | AE12: =(V12*$V$3)/(1800*$W$3) -> 8.3541258 | AF12: =(W12*$V$3)/(1800*$W$3) -> 7.4630191 | AG12: =(X12*$V$3)/(1800*$W$3) -> 8.3355611 | AH12: =(Y12*$V$3)/(1800*$W$3) -> 8.1127844 | AI12: =(Z12*$V$3)/(1800*$W$3) -> 5.9964059 | AJ12: =(AA12*$V$3)/(1800*$W$3) -> 5.0867344 | AL12: 0.5 | AM12: =Roster!G$55+Roster!G$56 -> 24 | AN12: =Roster!H$55+Roster!H$56 -> 19 | AO12: =Roster!I$55+Roster!I$56 -> 19 | AP12: =Roster!J$55+Roster!J$56 -> 15 | AQ12: =Roster!K$55+Roster!K$56 -> 15 | AR12: =Roster!L$55+Roster!L$56 -> 15 | AS12: =Roster!M$55+Roster!M$56 -> 15 | AU12: 0.5 | AV12: =AM12*(1-32%) -> 16.32 | AW12: =AN12*(1-32%) -> 12.92 | AX12: =AO12*(1-32%) -> 12.92 | AY12: =AP12*(1-32%) -> 10.2 | AZ12: =AQ12*(1-32%) -> 10.2 | BA12: =AR12*(1-32%) -> 10.2 | BB12: =AS12*(1-32%) -> 10.2 | BD12: 0.5 | BE12: =AV12*1800*$W$3/300 -> 78.336 | BF12: =AW12*1800*$W$3/300 -> 62.016 | BG12: =AX12*1800*$W$3/300 -> 62.016 | BH12: =AY12*1800*$W$3/300 -> 48.96 | BI12: =AZ12*1800*$W$3/300 -> 48.96 | BJ12: =BA12*1800*$W$3/300 -> 48.96 | BK12: =BB12*1800*$W$3/300 -> 48.96 | BM12: 0.5 | BN12: =AV12-AD12 -> 6.6477788 | BO12: =AW12-AE12 -> 4.5658742 | BP12: =AX12-AF12 -> 5.4569809 | BQ12: =AY12-AG12 -> 1.8644389 | BR12: =AZ12-AH12 -> 2.0872156 | BS12: =BA12-AI12 -> 4.2035941 | BT12: =BB12-AJ12 -> 5.1132656 | BV12: 0.5 | BW12: =BE12-U12 -> 31.909338 | BX12: =BF12-V12 -> 21.916196 | BY12: =BG12-W12 -> 26.193508 | BZ12: =BH12-X12 -> 8.9493067 | CA12: =BI12-Y12 -> 10.018635 | CB12: =BJ12-Z12 -> 20.177252 | CC12: =BK12-AA12 -> 24.543675
B13: 0.52083333 | C13: 78.833333 | D13: 74.833333 | E13: 64.833333 | F13: 73.833333 | G13: 63.833333 | H13: 58.833333 | I13: 37.666667 | K13: 0.52083333 | L13: 0.039462706 | M13: 0.041087116 | N13: 0.036196148 | O13: 0.040690732 | P13: 0.039779809 | Q13: 0.04967633 | R13: 0.037355372 | T13: 0.52083333 | U13: =$U$3*C$37*L13 -> 42.149349 | V13: =$U$3*D$37*M13 -> 40.010693 | W13: =$U$3*E$37*N13 -> 34.664053 | X13: =$U$3*F$37*O13 -> 39.476029 | Y13: =$U$3*G$37*P13 -> 34.129389 | Z13: =$U$3*H$37*Q13 -> 31.456068 | AA13: =$U$3*I$37*R13 -> 20.139013 | AC13: 0.52083333 | AD13: =(U13*$V$3)/(1800*$W$3) -> 8.7811145 | AE13: =(V13*$V$3)/(1800*$W$3) -> 8.3355611 | AF13: =(W13*$V$3)/(1800*$W$3) -> 7.2216777 | AG13: =(X13*$V$3)/(1800*$W$3) -> 8.2241728 | AH13: =(Y13*$V$3)/(1800*$W$3) -> 7.1102893 | AI13: =(Z13*$V$3)/(1800*$W$3) -> 6.5533476 | AJ13: =(AA13*$V$3)/(1800*$W$3) -> 4.1956276 | AL13: 0.52083333 | AM13: =Roster!G$55+Roster!G$56 -> 24 | AN13: =Roster!H$55+Roster!H$56 -> 19 | AO13: =Roster!I$55+Roster!I$56 -> 19 | AP13: =Roster!J$55+Roster!J$56 -> 15 | AQ13: =Roster!K$55+Roster!K$56 -> 15 | AR13: =Roster!L$55+Roster!L$56 -> 15 | AS13: =Roster!M$55+Roster!M$56 -> 15 | AU13: 0.52083333 | AV13: =AM13*(1-32%) -> 16.32 | AW13: =AN13*(1-32%) -> 12.92 | AX13: =AO13*(1-32%) -> 12.92 | AY13: =AP13*(1-32%) -> 10.2 | AZ13: =AQ13*(1-32%) -> 10.2 | BA13: =AR13*(1-32%) -> 10.2 | BB13: =AS13*(1-32%) -> 10.2 | BD13: 0.52083333 | BE13: =AV13*1800*$W$3/300 -> 78.336 | BF13: =AW13*1800*$W$3/300 -> 62.016 | BG13: =AX13*1800*$W$3/300 -> 62.016 | BH13: =AY13*1800*$W$3/300 -> 48.96 | BI13: =AZ13*1800*$W$3/300 -> 48.96 | BJ13: =BA13*1800*$W$3/300 -> 48.96 | BK13: =BB13*1800*$W$3/300 -> 48.96 | BM13: 0.52083333 | BN13: =AV13-AD13 -> 7.5388855 | BO13: =AW13-AE13 -> 4.5844389 | BP13: =AX13-AF13 -> 5.6983223 | BQ13: =AY13-AG13 -> 1.9758272 | BR13: =AZ13-AH13 -> 3.0897107 | BS13: =BA13-AI13 -> 3.6466524 | BT13: =BB13-AJ13 -> 6.0043724 | BV13: 0.52083333 | BW13: =BE13-U13 -> 36.186651 | BX13: =BF13-V13 -> 22.005307 | BY13: =BG13-W13 -> 27.351947 | BZ13: =BH13-X13 -> 9.4839708 | CA13: =BI13-Y13 -> 14.830611 | CB13: =BJ13-Z13 -> 17.503932 | CC13: =BK13-AA13 -> 28.820987
B14: 0.54166667 | C14: 82.833333 | D14: 81.833333 | E14: 70 | F14: 82.833333 | G14: 64.833333 | H14: 50.833333 | I14: 44.666667 | K14: 0.54166667 | L14: 0.041465043 | M14: 0.044930454 | N14: 0.039080674 | O14: 0.045650776 | P14: 0.040402991 | Q14: 0.042921475 | R14: 0.044297521 | T14: 0.54166667 | U14: =$U$3*C$37*L14 -> 44.288006 | V14: =$U$3*D$37*M14 -> 43.753342 | W14: =$U$3*E$37*N14 -> 37.426484 | X14: =$U$3*F$37*O14 -> 44.288006 | Y14: =$U$3*G$37*P14 -> 34.664053 | Z14: =$U$3*H$37*Q14 -> 27.178756 | AA14: =$U$3*I$37*R14 -> 23.881661 | AC14: 0.54166667 | AD14: =(U14*$V$3)/(1800*$W$3) -> 9.2266679 | AE14: =(V14*$V$3)/(1800*$W$3) -> 9.1152795 | AF14: =(W14*$V$3)/(1800*$W$3) -> 7.7971841 | AG14: =(X14*$V$3)/(1800*$W$3) -> 9.2266679 | AH14: =(Y14*$V$3)/(1800*$W$3) -> 7.2216777 | AI14: =(Z14*$V$3)/(1800*$W$3) -> 5.6622408 | AJ14: =(AA14*$V$3)/(1800*$W$3) -> 4.975346 | AL14: 0.54166667 | AM14: =Roster!G$55+Roster!G$56+Roster!G$59 -> 32 | AN14: =Roster!H$55+Roster!H$56+Roster!H$59 -> 27 | AO14: =Roster!I$55+Roster!I$56+Roster!I$59 -> 27 | AP14: =Roster!J$55+Roster!J$56+Roster!J$59 -> 20 | AQ14: =Roster!K$55+Roster!K$56+Roster!K$59 -> 20 | AR14: =Roster!L$55+Roster!L$56+Roster!L$59 -> 18 | AS14: =Roster!M$55+Roster!M$56+Roster!M$59 -> 18 | AU14: 0.54166667 | AV14: =AM14*(1-32%) -> 21.76 | AW14: =AN14*(1-32%) -> 18.36 | AX14: =AO14*(1-32%) -> 18.36 | AY14: =AP14*(1-32%) -> 13.6 | AZ14: =AQ14*(1-32%) -> 13.6 | BA14: =AR14*(1-32%) -> 12.24 | BB14: =AS14*(1-32%) -> 12.24 | BD14: 0.54166667 | BE14: =AV14*1800*$W$3/300 -> 104.448 | BF14: =AW14*1800*$W$3/300 -> 88.128 | BG14: =AX14*1800*$W$3/300 -> 88.128 | BH14: =AY14*1800*$W$3/300 -> 65.28 | BI14: =AZ14*1800*$W$3/300 -> 65.28 | BJ14: =BA14*1800*$W$3/300 -> 58.752 | BK14: =BB14*1800*$W$3/300 -> 58.752 | BM14: 0.54166667 | BN14: =AV14-AD14 -> 12.533332 | BO14: =AW14-AE14 -> 9.2447205 | BP14: =AX14-AF14 -> 10.562816 | BQ14: =AY14-AG14 -> 4.3733321 | BR14: =AZ14-AH14 -> 6.3783223 | BS14: =BA14-AI14 -> 6.5777592 | BT14: =BB14-AJ14 -> 7.264654 | BV14: 0.54166667 | BW14: =BE14-U14 -> 60.159994 | BX14: =BF14-V14 -> 44.374658 | BY14: =BG14-W14 -> 50.701516 | BZ14: =BH14-X14 -> 20.991994 | CA14: =BI14-Y14 -> 30.615947 | CB14: =BJ14-Z14 -> 31.573244 | CC14: =BK14-AA14 -> 34.870339
B15: 0.5625 | C15: 83.833333 | D15: 82.833333 | E15: 77.833333 | F15: 71 | G15: 71.833333 | H15: 44.833333 | I15: 41.666667 | K15: 0.5625 | L15: 0.041965627 | M15: 0.045479502 | N15: 0.043453987 | O15: 0.039129237 | P15: 0.044765268 | Q15: 0.037855334 | R15: 0.041322314 | T15: 0.5625 | U15: =$U$3*C$37*L15 -> 44.82267 | V15: =$U$3*D$37*M15 -> 44.288006 | W15: =$U$3*E$37*N15 -> 41.614685 | X15: =$U$3*F$37*O15 -> 37.961148 | Y15: =$U$3*G$37*P15 -> 38.406701 | Z15: =$U$3*H$37*Q15 -> 23.970772 | AA15: =$U$3*I$37*R15 -> 22.277669 | AC15: 0.5625 | AD15: =(U15*$V$3)/(1800*$W$3) -> 9.3380562 | AE15: =(V15*$V$3)/(1800*$W$3) -> 9.2266679 | AF15: =(W15*$V$3)/(1800*$W$3) -> 8.6697261 | AG15: =(X15*$V$3)/(1800*$W$3) -> 7.9085724 | AH15: =(Y15*$V$3)/(1800*$W$3) -> 8.0013961 | AI15: =(Z15*$V$3)/(1800*$W$3) -> 4.9939108 | AJ15: =(AA15*$V$3)/(1800*$W$3) -> 4.641181 | AL15: 0.5625 | AM15: =Roster!G$55+Roster!G$56+Roster!G$59 -> 32 | AN15: =Roster!H$55+Roster!H$56+Roster!H$59 -> 27 | AO15: =Roster!I$55+Roster!I$56+Roster!I$59 -> 27 | AP15: =Roster!J$55+Roster!J$56+Roster!J$59 -> 20 | AQ15: =Roster!K$55+Roster!K$56+Roster!K$59 -> 20 | AR15: =Roster!L$55+Roster!L$56+Roster!L$59 -> 18 | AS15: =Roster!M$55+Roster!M$56+Roster!M$59 -> 18 | AU15: 0.5625 | AV15: =AM15*(1-32%) -> 21.76 | AW15: =AN15*(1-32%) -> 18.36 | AX15: =AO15*(1-32%) -> 18.36 | AY15: =AP15*(1-32%) -> 13.6 | AZ15: =AQ15*(1-32%) -> 13.6 | BA15: =AR15*(1-32%) -> 12.24 | BB15: =AS15*(1-32%) -> 12.24 | BD15: 0.5625 | BE15: =AV15*1800*$W$3/300 -> 104.448 | BF15: =AW15*1800*$W$3/300 -> 88.128 | BG15: =AX15*1800*$W$3/300 -> 88.128 | BH15: =AY15*1800*$W$3/300 -> 65.28 | BI15: =AZ15*1800*$W$3/300 -> 65.28 | BJ15: =BA15*1800*$W$3/300 -> 58.752 | BK15: =BB15*1800*$W$3/300 -> 58.752 | BM15: 0.5625 | BN15: =AV15-AD15 -> 12.421944 | BO15: =AW15-AE15 -> 9.1333321 | BP15: =AX15-AF15 -> 9.6902739 | BQ15: =AY15-AG15 -> 5.6914276 | BR15: =AZ15-AH15 -> 5.5986039 | BS15: =BA15-AI15 -> 7.2460892 | BT15: =BB15-AJ15 -> 7.598819 | BV15: 0.5625 | BW15: =BE15-U15 -> 59.62533 | BX15: =BF15-V15 -> 43.839994 | BY15: =BG15-W15 -> 46.513315 | BZ15: =BH15-X15 -> 27.318852 | CA15: =BI15-Y15 -> 26.873299 | CB15: =BJ15-Z15 -> 34.781228 | CC15: =BK15-AA15 -> 36.474331
B16: 0.58333333 | C16: 88.833333 | D16: 76.833333 | E16: 83.833333 | F16: 77.833333 | G16: 71.833333 | H16: 41.666667 | I16: 41.666667 | K16: 0.58333333 | L16: 0.044468547 | M16: 0.042185212 | N16: 0.046803759 | O16: 0.042895196 | P16: 0.044765268 | Q16: 0.035181537 | R16: 0.041322314 | T16: 0.58333333 | U16: =$U$3*C$37*L16 -> 47.49599 | V16: =$U$3*D$37*M16 -> 41.080021 | W16: =$U$3*E$37*N16 -> 44.82267 | X16: =$U$3*F$37*O16 -> 41.614685 | Y16: =$U$3*G$37*P16 -> 38.406701 | Z16: =$U$3*H$37*Q16 -> 22.277669 | AA16: =$U$3*I$37*R16 -> 22.277669 | AC16: 0.58333333 | AD16: =(U16*$V$3)/(1800*$W$3) -> 9.8949979 | AE16: =(V16*$V$3)/(1800*$W$3) -> 8.5583378 | AF16: =(W16*$V$3)/(1800*$W$3) -> 9.3380562 | AG16: =(X16*$V$3)/(1800*$W$3) -> 8.6697261 | AH16: =(Y16*$V$3)/(1800*$W$3) -> 8.0013961 | AI16: =(Z16*$V$3)/(1800*$W$3) -> 4.641181 | AJ16: =(AA16*$V$3)/(1800*$W$3) -> 4.641181 | AL16: 0.58333333 | AM16: =Roster!G$55+Roster!G$56+Roster!G$59+Roster!G$60+Roster!G$61 -> 39 | AN16: =Roster!H$55+Roster!H$56+Roster!H$59+Roster!H$60+Roster!H$61 -> 34 | AO16: =Roster!I$55+Roster!I$56+Roster!I$59+Roster!I$60+Roster!I$61 -> 37 | AP16: =Roster!J$55+Roster!J$56+Roster!J$59+Roster!J$60+Roster!J$61 -> 26 | AQ16: =Roster!K$55+Roster!K$56+Roster!K$59+Roster!K$60+Roster!K$61 -> 26 | AR16: =Roster!L$55+Roster!L$56+Roster!L$59+Roster!L$60+Roster!L$61 -> 27 | AS16: =Roster!M$55+Roster!M$56+Roster!M$59+Roster!M$60+Roster!M$61 -> 27 | AU16: 0.58333333 | AV16: =AM16*(1-32%) -> 26.52 | AW16: =AN16*(1-32%) -> 23.12 | AX16: =AO16*(1-32%) -> 25.16 | AY16: =AP16*(1-32%) -> 17.68 | AZ16: =AQ16*(1-32%) -> 17.68 | BA16: =AR16*(1-32%) -> 18.36 | BB16: =AS16*(1-32%) -> 18.36 | BD16: 0.58333333 | BE16: =AV16*1800*$W$3/300 -> 127.296 | BF16: =AW16*1800*$W$3/300 -> 110.976 | BG16: =AX16*1800*$W$3/300 -> 120.768 | BH16: =AY16*1800*$W$3/300 -> 84.864 | BI16: =AZ16*1800*$W$3/300 -> 84.864 | BJ16: =BA16*1800*$W$3/300 -> 88.128 | BK16: =BB16*1800*$W$3/300 -> 88.128 | BM16: 0.58333333 | BN16: =AV16-AD16 -> 16.625002 | BO16: =AW16-AE16 -> 14.561662 | BP16: =AX16-AF16 -> 15.821944 | BQ16: =AY16-AG16 -> 9.0102739 | BR16: =AZ16-AH16 -> 9.6786039 | BS16: =BA16-AI16 -> 13.718819 | BT16: =BB16-AJ16 -> 13.718819 | BV16: 0.58333333 | BW16: =BE16-U16 -> 79.80001 | BX16: =BF16-V16 -> 69.895979 | BY16: =BG16-W16 -> 75.94533 | BZ16: =BH16-X16 -> 43.249315 | CA16: =BI16-Y16 -> 46.457299 | CB16: =BJ16-Z16 -> 65.850331 | CC16: =BK16-AA16 -> 65.850331
B17: 0.60416667 | C17: 102.83333 | D17: 81.833333 | E17: 86.833333 | F17: 79.833333 | G17: 71.833333 | H17: 51.833333 | I17: 47.666667 | K17: 0.60416667 | L17: 0.051476723 | M17: 0.044930454 | N17: 0.048478645 | O17: 0.043997428 | P17: 0.044765268 | Q17: 0.043765832 | R17: 0.047272727 | T17: 0.60416667 | U17: =$U$3*C$37*L17 -> 54.981287 | V17: =$U$3*D$37*M17 -> 43.753342 | W17: =$U$3*E$37*N17 -> 46.426662 | X17: =$U$3*F$37*O17 -> 42.684014 | Y17: =$U$3*G$37*P17 -> 38.406701 | Z17: =$U$3*H$37*Q17 -> 27.71342 | AA17: =$U$3*I$37*R17 -> 25.485653 | AC17: 0.60416667 | AD17: =(U17*$V$3)/(1800*$W$3) -> 11.454435 | AE17: =(V17*$V$3)/(1800*$W$3) -> 9.1152795 | AF17: =(W17*$V$3)/(1800*$W$3) -> 9.6722212 | AG17: =(X17*$V$3)/(1800*$W$3) -> 8.8925028 | AH17: =(Y17*$V$3)/(1800*$W$3) -> 8.0013961 | AI17: =(Z17*$V$3)/(1800*$W$3) -> 5.7736292 | AJ17: =(AA17*$V$3)/(1800*$W$3) -> 5.3095111 | AL17: 0.60416667 | AM17: =Roster!G$55+Roster!G$56+Roster!G$59+Roster!G$60+Roster!G$61 -> 39 | AN17: =Roster!H$55+Roster!H$56+Roster!H$59+Roster!H$60+Roster!H$61 -> 34 | AO17: =Roster!I$55+Roster!I$56+Roster!I$59+Roster!I$60+Roster!I$61 -> 37 | AP17: =Roster!J$55+Roster!J$56+Roster!J$59+Roster!J$60+Roster!J$61 -> 26 | AQ17: =Roster!K$55+Roster!K$56+Roster!K$59+Roster!K$60+Roster!K$61 -> 26 | AR17: =Roster!L$55+Roster!L$56+Roster!L$59+Roster!L$60+Roster!L$61 -> 27 | AS17: =Roster!M$55+Roster!M$56+Roster!M$59+Roster!M$60+Roster!M$61 -> 27 | AU17: 0.60416667 | AV17: =AM17*(1-32%) -> 26.52 | AW17: =AN17*(1-32%) -> 23.12 | AX17: =AO17*(1-32%) -> 25.16 | AY17: =AP17*(1-32%) -> 17.68 | AZ17: =AQ17*(1-32%) -> 17.68 | BA17: =AR17*(1-32%) -> 18.36 | BB17: =AS17*(1-32%) -> 18.36 | BD17: 0.60416667 | BE17: =AV17*1800*$W$3/300 -> 127.296 | BF17: =AW17*1800*$W$3/300 -> 110.976 | BG17: =AX17*1800*$W$3/300 -> 120.768 | BH17: =AY17*1800*$W$3/300 -> 84.864 | BI17: =AZ17*1800*$W$3/300 -> 84.864 | BJ17: =BA17*1800*$W$3/300 -> 88.128 | BK17: =BB17*1800*$W$3/300 -> 88.128 | BM17: 0.60416667 | BN17: =AV17-AD17 -> 15.065565 | BO17: =AW17-AE17 -> 14.00472 | BP17: =AX17-AF17 -> 15.487779 | BQ17: =AY17-AG17 -> 8.7874972 | BR17: =AZ17-AH17 -> 9.6786039 | BS17: =BA17-AI17 -> 12.586371 | BT17: =BB17-AJ17 -> 13.050489 | BV17: 0.60416667 | BW17: =BE17-U17 -> 72.314713 | BX17: =BF17-V17 -> 67.222658 | BY17: =BG17-W17 -> 74.341338 | BZ17: =BH17-X17 -> 42.179986 | CA17: =BI17-Y17 -> 46.457299 | CB17: =BJ17-Z17 -> 60.41458 | CC17: =BK17-AA17 -> 62.642347
B18: 0.625 | C18: 85.833333 | D18: 83.833333 | E18: 83.833333 | F18: 80.833333 | G18: 66.833333 | H18: 52.833333 | I18: 40.666667 | K18: 0.625 | L18: 0.042966795 | M18: 0.046028551 | N18: 0.046803759 | O18: 0.044548544 | P18: 0.041649356 | Q18: 0.044610189 | R18: 0.040330579 | T18: 0.625 | U18: =$U$3*C$37*L18 -> 45.891998 | V18: =$U$3*D$37*M18 -> 44.82267 | W18: =$U$3*E$37*N18 -> 44.82267 | X18: =$U$3*F$37*O18 -> 43.218678 | Y18: =$U$3*G$37*P18 -> 35.733381 | Z18: =$U$3*H$37*Q18 -> 28.248084 | AA18: =$U$3*I$37*R18 -> 21.743005 | AC18: 0.625 | AD18: =(U18*$V$3)/(1800*$W$3) -> 9.5608329 | AE18: =(V18*$V$3)/(1800*$W$3) -> 9.3380562 | AF18: =(W18*$V$3)/(1800*$W$3) -> 9.3380562 | AG18: =(X18*$V$3)/(1800*$W$3) -> 9.0038912 | AH18: =(Y18*$V$3)/(1800*$W$3) -> 7.4444543 | AI18: =(Z18*$V$3)/(1800*$W$3) -> 5.8850175 | AJ18: =(AA18*$V$3)/(1800*$W$3) -> 4.5297927 | AL18: 0.625 | AM18: =Roster!G$55+Roster!G$56+Roster!G$59+Roster!G$60+Roster!G$61 -> 39 | AN18: =Roster!H$55+Roster!H$56+Roster!H$59+Roster!H$60+Roster!H$61 -> 34 | AO18: =Roster!I$55+Roster!I$56+Roster!I$59+Roster!I$60+Roster!I$61 -> 37 | AP18: =Roster!J$55+Roster!J$56+Roster!J$59+Roster!J$60+Roster!J$61 -> 26 | AQ18: =Roster!K$55+Roster!K$56+Roster!K$59+Roster!K$60+Roster!K$61 -> 26 | AR18: =Roster!L$55+Roster!L$56+Roster!L$59+Roster!L$60+Roster!L$61 -> 27 | AS18: =Roster!M$55+Roster!M$56+Roster!M$59+Roster!M$60+Roster!M$61 -> 27 | AU18: 0.625 | AV18: =AM18*(1-32%) -> 26.52 | AW18: =AN18*(1-32%) -> 23.12 | AX18: =AO18*(1-32%) -> 25.16 | AY18: =AP18*(1-32%) -> 17.68 | AZ18: =AQ18*(1-32%) -> 17.68 | BA18: =AR18*(1-32%) -> 18.36 | BB18: =AS18*(1-32%) -> 18.36 | BD18: 0.625 | BE18: =AV18*1800*$W$3/300 -> 127.296 | BF18: =AW18*1800*$W$3/300 -> 110.976 | BG18: =AX18*1800*$W$3/300 -> 120.768 | BH18: =AY18*1800*$W$3/300 -> 84.864 | BI18: =AZ18*1800*$W$3/300 -> 84.864 | BJ18: =BA18*1800*$W$3/300 -> 88.128 | BK18: =BB18*1800*$W$3/300 -> 88.128 | BM18: 0.625 | BN18: =AV18-AD18 -> 16.959167 | BO18: =AW18-AE18 -> 13.781944 | BP18: =AX18-AF18 -> 15.821944 | BQ18: =AY18-AG18 -> 8.6761088 | BR18: =AZ18-AH18 -> 10.235546 | BS18: =BA18-AI18 -> 12.474982 | BT18: =BB18-AJ18 -> 13.830207 | BV18: 0.625 | BW18: =BE18-U18 -> 81.404002 | BX18: =BF18-V18 -> 66.15333 | BY18: =BG18-W18 -> 75.94533 | BZ18: =BH18-X18 -> 41.645322 | CA18: =BI18-Y18 -> 49.130619 | CB18: =BJ18-Z18 -> 59.879916 | CC18: =BK18-AA18 -> 66.384995
B19: 0.64583333 | C19: 94.833333 | D19: 89.833333 | E19: 82.833333 | F19: 81.833333 | G19: 76.833333 | H19: 55.833333 | I19: 43.666667 | K19: 0.64583333 | L19: 0.047472051 | M19: 0.04932284 | N19: 0.046245464 | O19: 0.04509966 | P19: 0.04788118 | Q19: 0.047143259 | R19: 0.043305785 | T19: 0.64583333 | U19: =$U$3*C$37*L19 -> 50.703974 | V19: =$U$3*D$37*M19 -> 48.030654 | W19: =$U$3*E$37*N19 -> 44.288006 | X19: =$U$3*F$37*O19 -> 43.753342 | Y19: =$U$3*G$37*P19 -> 41.080021 | Z19: =$U$3*H$37*Q19 -> 29.852076 | AA19: =$U$3*I$37*R19 -> 23.346997 | AC19: 0.64583333 | AD19: =(U19*$V$3)/(1800*$W$3) -> 10.563328 | AE19: =(V19*$V$3)/(1800*$W$3) -> 10.006386 | AF19: =(W19*$V$3)/(1800*$W$3) -> 9.2266679 | AG19: =(X19*$V$3)/(1800*$W$3) -> 9.1152795 | AH19: =(Y19*$V$3)/(1800*$W$3) -> 8.5583378 | AI19: =(Z19*$V$3)/(1800*$W$3) -> 6.2191826 | AJ19: =(AA19*$V$3)/(1800*$W$3) -> 4.8639577 | AL19: 0.64583333 | AM19: =Roster!G$55+Roster!G$56+Roster!G$59+Roster!G$60+Roster!G$61 -> 39 | AN19: =Roster!H$55+Roster!H$56+Roster!H$59+Roster!H$60+Roster!H$61 -> 34 | AO19: =Roster!I$55+Roster!I$56+Roster!I$59+Roster!I$60+Roster!I$61 -> 37 | AP19: =Roster!J$55+Roster!J$56+Roster!J$59+Roster!J$60+Roster!J$61 -> 26 | AQ19: =Roster!K$55+Roster!K$56+Roster!K$59+Roster!K$60+Roster!K$61 -> 26 | AR19: =Roster!L$55+Roster!L$56+Roster!L$59+Roster!L$60+Roster!L$61 -> 27 | AS19: =Roster!M$55+Roster!M$56+Roster!M$59+Roster!M$60+Roster!M$61 -> 27 | AU19: 0.64583333 | AV19: =AM19*(1-32%) -> 26.52 | AW19: =AN19*(1-32%) -> 23.12 | AX19: =AO19*(1-32%) -> 25.16 | AY19: =AP19*(1-32%) -> 17.68 | AZ19: =AQ19*(1-32%) -> 17.68 | BA19: =AR19*(1-32%) -> 18.36 | BB19: =AS19*(1-32%) -> 18.36 | BD19: 0.64583333 | BE19: =AV19*1800*$W$3/300 -> 127.296 | BF19: =AW19*1800*$W$3/300 -> 110.976 | BG19: =AX19*1800*$W$3/300 -> 120.768 | BH19: =AY19*1800*$W$3/300 -> 84.864 | BI19: =AZ19*1800*$W$3/300 -> 84.864 | BJ19: =BA19*1800*$W$3/300 -> 88.128 | BK19: =BB19*1800*$W$3/300 -> 88.128 | BM19: 0.64583333 | BN19: =AV19-AD19 -> 15.956672 | BO19: =AW19-AE19 -> 13.113614 | BP19: =AX19-AF19 -> 15.933332 | BQ19: =AY19-AG19 -> 8.5647205 | BR19: =AZ19-AH19 -> 9.1216622 | BS19: =BA19-AI19 -> 12.140817 | BT19: =BB19-AJ19 -> 13.496042 | BV19: 0.64583333 | BW19: =BE19-U19 -> 76.592026 | BX19: =BF19-V19 -> 62.945346 | BY19: =BG19-W19 -> 76.479994 | BZ19: =BH19-X19 -> 41.110658 | CA19: =BI19-Y19 -> 43.783979 | CB19: =BJ19-Z19 -> 58.275924 | CC19: =BK19-AA19 -> 64.781003
B20: 0.66666667 | C20: 88.833333 | D20: 84.833333 | E20: 77.833333 | F20: 87.833333 | G20: 73.833333 | H20: 45.833333 | I20: 32.666667 | K20: 0.66666667 | L20: 0.044468547 | M20: 0.046577599 | N20: 0.043453987 | O20: 0.048406356 | P20: 0.046011633 | Q20: 0.03869969 | R20: 0.032396694 | T20: 0.66666667 | U20: =$U$3*C$37*L20 -> 47.49599 | V20: =$U$3*D$37*M20 -> 45.357334 | W20: =$U$3*E$37*N20 -> 41.614685 | X20: =$U$3*F$37*O20 -> 46.961326 | Y20: =$U$3*G$37*P20 -> 39.476029 | Z20: =$U$3*H$37*Q20 -> 24.505436 | AA20: =$U$3*I$37*R20 -> 17.465692 | AC20: 0.66666667 | AD20: =(U20*$V$3)/(1800*$W$3) -> 9.8949979 | AE20: =(V20*$V$3)/(1800*$W$3) -> 9.4494445 | AF20: =(W20*$V$3)/(1800*$W$3) -> 8.6697261 | AG20: =(X20*$V$3)/(1800*$W$3) -> 9.7836096 | AH20: =(Y20*$V$3)/(1800*$W$3) -> 8.2241728 | AI20: =(Z20*$V$3)/(1800*$W$3) -> 5.1052991 | AJ20: =(AA20*$V$3)/(1800*$W$3) -> 3.6386859 | AL20: 0.66666667 | AM20: =Roster!G$55+Roster!G$56+Roster!G$59+Roster!G$60+Roster!G$61 -> 39 | AN20: =Roster!H$55+Roster!H$56+Roster!H$59+Roster!H$60+Roster!H$61 -> 34 | AO20: =Roster!I$55+Roster!I$56+Roster!I$59+Roster!I$60+Roster!I$61 -> 37 | AP20: =Roster!J$55+Roster!J$56+Roster!J$59+Roster!J$60+Roster!J$61 -> 26 | AQ20: =Roster!K$55+Roster!K$56+Roster!K$59+Roster!K$60+Roster!K$61 -> 26 | AR20: =Roster!L$55+Roster!L$56+Roster!L$59+Roster!L$60+Roster!L$61 -> 27 | AS20: =Roster!M$55+Roster!M$56+Roster!M$59+Roster!M$60+Roster!M$61 -> 27 | AU20: 0.66666667 | AV20: =AM20*(1-32%) -> 26.52 | AW20: =AN20*(1-32%) -> 23.12 | AX20: =AO20*(1-32%) -> 25.16 | AY20: =AP20*(1-32%) -> 17.68 | AZ20: =AQ20*(1-32%) -> 17.68 | BA20: =AR20*(1-32%) -> 18.36 | BB20: =AS20*(1-32%) -> 18.36 | BD20: 0.66666667 | BE20: =AV20*1800*$W$3/300 -> 127.296 | BF20: =AW20*1800*$W$3/300 -> 110.976 | BG20: =AX20*1800*$W$3/300 -> 120.768 | BH20: =AY20*1800*$W$3/300 -> 84.864 | BI20: =AZ20*1800*$W$3/300 -> 84.864 | BJ20: =BA20*1800*$W$3/300 -> 88.128 | BK20: =BB20*1800*$W$3/300 -> 88.128 | BM20: 0.66666667 | BN20: =AV20-AD20 -> 16.625002 | BO20: =AW20-AE20 -> 13.670555 | BP20: =AX20-AF20 -> 16.490274 | BQ20: =AY20-AG20 -> 7.8963904 | BR20: =AZ20-AH20 -> 9.4558272 | BS20: =BA20-AI20 -> 13.254701 | BT20: =BB20-AJ20 -> 14.721314 | BV20: 0.66666667 | BW20: =BE20-U20 -> 79.80001 | BX20: =BF20-V20 -> 65.618666 | BY20: =BG20-W20 -> 79.153315 | BZ20: =BH20-X20 -> 37.902674 | CA20: =BI20-Y20 -> 45.387971 | CB20: =BJ20-Z20 -> 63.622564 | CC20: =BK20-AA20 -> 70.662308
B21: 0.6875 | C21: 81.833333 | D21: 71.833333 | E21: 68.833333 | F21: 73.833333 | G21: 76.833333 | H21: 42.833333 | I21: 40.666667 | K21: 0.6875 | L21: 0.040964459 | M21: 0.039439971 | N21: 0.038429329 | O21: 0.040690732 | P21: 0.04788118 | Q21: 0.03616662 | R21: 0.040330579 | T21: 0.6875 | U21: =$U$3*C$37*L21 -> 43.753342 | V21: =$U$3*D$37*M21 -> 38.406701 | W21: =$U$3*E$37*N21 -> 36.802709 | X21: =$U$3*F$37*O21 -> 39.476029 | Y21: =$U$3*G$37*P21 -> 41.080021 | Z21: =$U$3*H$37*Q21 -> 22.901444 | AA21: =$U$3*I$37*R21 -> 21.743005 | AC21: 0.6875 | AD21: =(U21*$V$3)/(1800*$W$3) -> 9.1152795 | AE21: =(V21*$V$3)/(1800*$W$3) -> 8.0013961 | AF21: =(W21*$V$3)/(1800*$W$3) -> 7.667231 | AG21: =(X21*$V$3)/(1800*$W$3) -> 8.2241728 | AH21: =(Y21*$V$3)/(1800*$W$3) -> 8.5583378 | AI21: =(Z21*$V$3)/(1800*$W$3) -> 4.7711341 | AJ21: =(AA21*$V$3)/(1800*$W$3) -> 4.5297927 | AL21: 0.6875 | AM21: =Roster!G$55+Roster!G$56+Roster!G$59+Roster!G$60+Roster!G$61 -> 39 | AN21: =Roster!H$55+Roster!H$56+Roster!H$59+Roster!H$60+Roster!H$61 -> 34 | AO21: =Roster!I$55+Roster!I$56+Roster!I$59+Roster!I$60+Roster!I$61 -> 37 | AP21: =Roster!J$55+Roster!J$56+Roster!J$59+Roster!J$60+Roster!J$61 -> 26 | AQ21: =Roster!K$55+Roster!K$56+Roster!K$59+Roster!K$60+Roster!K$61 -> 26 | AR21: =Roster!L$55+Roster!L$56+Roster!L$59+Roster!L$60+Roster!L$61 -> 27 | AS21: =Roster!M$55+Roster!M$56+Roster!M$59+Roster!M$60+Roster!M$61 -> 27 | AU21: 0.6875 | AV21: =AM21*(1-32%) -> 26.52 | AW21: =AN21*(1-32%) -> 23.12 | AX21: =AO21*(1-32%) -> 25.16 | AY21: =AP21*(1-32%) -> 17.68 | AZ21: =AQ21*(1-32%) -> 17.68 | BA21: =AR21*(1-32%) -> 18.36 | BB21: =AS21*(1-32%) -> 18.36 | BD21: 0.6875 | BE21: =AV21*1800*$W$3/300 -> 127.296 | BF21: =AW21*1800*$W$3/300 -> 110.976 | BG21: =AX21*1800*$W$3/300 -> 120.768 | BH21: =AY21*1800*$W$3/300 -> 84.864 | BI21: =AZ21*1800*$W$3/300 -> 84.864 | BJ21: =BA21*1800*$W$3/300 -> 88.128 | BK21: =BB21*1800*$W$3/300 -> 88.128 | BM21: 0.6875 | BN21: =AV21-AD21 -> 17.40472 | BO21: =AW21-AE21 -> 15.118604 | BP21: =AX21-AF21 -> 17.492769 | BQ21: =AY21-AG21 -> 9.4558272 | BR21: =AZ21-AH21 -> 9.1216622 | BS21: =BA21-AI21 -> 13.588866 | BT21: =BB21-AJ21 -> 13.830207 | BV21: 0.6875 | BW21: =BE21-U21 -> 83.542658 | BX21: =BF21-V21 -> 72.569299 | BY21: =BG21-W21 -> 83.965291 | BZ21: =BH21-X21 -> 45.387971 | CA21: =BI21-Y21 -> 43.783979 | CB21: =BJ21-Z21 -> 65.226556 | CC21: =BK21-AA21 -> 66.384995
B22: 0.70833333 | C22: 84.833333 | D22: 70.833333 | E22: 70.833333 | F22: 79.833333 | G22: 62.833333 | H22: 43.833333 | I22: 35.666667 | K22: 0.70833333 | L22: 0.042466211 | M22: 0.038890922 | N22: 0.03954592 | O22: 0.043997428 | P22: 0.039156627 | Q22: 0.037010977 | R22: 0.035371901 | T22: 0.70833333 | U22: =$U$3*C$37*L22 -> 45.357334 | V22: =$U$3*D$37*M22 -> 37.872037 | W22: =$U$3*E$37*N22 -> 37.872037 | X22: =$U$3*F$37*O22 -> 42.684014 | Y22: =$U$3*G$37*P22 -> 33.594725 | Z22: =$U$3*H$37*Q22 -> 23.436108 | AA22: =$U$3*I$37*R22 -> 19.069685 | AC22: 0.70833333 | AD22: =(U22*$V$3)/(1800*$W$3) -> 9.4494445 | AE22: =(V22*$V$3)/(1800*$W$3) -> 7.8900077 | AF22: =(W22*$V$3)/(1800*$W$3) -> 7.8900077 | AG22: =(X22*$V$3)/(1800*$W$3) -> 8.8925028 | AH22: =(Y22*$V$3)/(1800*$W$3) -> 6.998901 | AI22: =(Z22*$V$3)/(1800*$W$3) -> 4.8825224 | AJ22: =(AA22*$V$3)/(1800*$W$3) -> 3.9728509 | AL22: 0.70833333 | AM22: =Roster!G$55+Roster!G$56+Roster!G$59+Roster!G$60+Roster!G$61 -> 39 | AN22: =Roster!H$55+Roster!H$56+Roster!H$59+Roster!H$60+Roster!H$61 -> 34 | AO22: =Roster!I$55+Roster!I$56+Roster!I$59+Roster!I$60+Roster!I$61 -> 37 | AP22: =Roster!J$55+Roster!J$56+Roster!J$59+Roster!J$60+Roster!J$61 -> 26 | AQ22: =Roster!K$55+Roster!K$56+Roster!K$59+Roster!K$60+Roster!K$61 -> 26 | AR22: =Roster!L$55+Roster!L$56+Roster!L$59+Roster!L$60+Roster!L$61 -> 27 | AS22: =Roster!M$55+Roster!M$56+Roster!M$59+Roster!M$60+Roster!M$61 -> 27 | AU22: 0.70833333 | AV22: =AM22*(1-32%) -> 26.52 | AW22: =AN22*(1-32%) -> 23.12 | AX22: =AO22*(1-32%) -> 25.16 | AY22: =AP22*(1-32%) -> 17.68 | AZ22: =AQ22*(1-32%) -> 17.68 | BA22: =AR22*(1-32%) -> 18.36 | BB22: =AS22*(1-32%) -> 18.36 | BD22: 0.70833333 | BE22: =AV22*1800*$W$3/300 -> 127.296 | BF22: =AW22*1800*$W$3/300 -> 110.976 | BG22: =AX22*1800*$W$3/300 -> 120.768 | BH22: =AY22*1800*$W$3/300 -> 84.864 | BI22: =AZ22*1800*$W$3/300 -> 84.864 | BJ22: =BA22*1800*$W$3/300 -> 88.128 | BK22: =BB22*1800*$W$3/300 -> 88.128 | BM22: 0.70833333 | BN22: =AV22-AD22 -> 17.070555 | BO22: =AW22-AE22 -> 15.229992 | BP22: =AX22-AF22 -> 17.269992 | BQ22: =AY22-AG22 -> 8.7874972 | BR22: =AZ22-AH22 -> 10.681099 | BS22: =BA22-AI22 -> 13.477478 | BT22: =BB22-AJ22 -> 14.387149 | BV22: 0.70833333 | BW22: =BE22-U22 -> 81.938666 | BX22: =BF22-V22 -> 73.103963 | BY22: =BG22-W22 -> 82.895963 | BZ22: =BH22-X22 -> 42.179986 | CA22: =BI22-Y22 -> 51.269275 | CB22: =BJ22-Z22 -> 64.691892 | CC22: =BK22-AA22 -> 69.058315
B23: 0.72916667 | C23: 64.833333 | D23: 60.833333 | E23: 49.833333 | F23: 62.833333 | G23: 54.833333 | H23: 37.833333 | I23: 39.666667 | K23: 0.72916667 | L23: 0.03245453 | M23: 0.033400439 | N23: 0.027821718 | O23: 0.034628456 | P23: 0.034171167 | Q23: 0.031944835 | R23: 0.039338843 | T23: 0.72916667 | U23: =$U$3*C$37*L23 -> 34.664053 | V23: =$U$3*D$37*M23 -> 32.525397 | W23: =$U$3*E$37*N23 -> 26.644092 | X23: =$U$3*F$37*O23 -> 33.594725 | Y23: =$U$3*G$37*P23 -> 29.317412 | Z23: =$U$3*H$37*Q23 -> 20.228123 | AA23: =$U$3*I$37*R23 -> 21.208341 | AC23: 0.72916667 | AD23: =(U23*$V$3)/(1800*$W$3) -> 7.2216777 | AE23: =(V23*$V$3)/(1800*$W$3) -> 6.7761243 | AF23: =(W23*$V$3)/(1800*$W$3) -> 5.5508525 | AG23: =(X23*$V$3)/(1800*$W$3) -> 6.998901 | AH23: =(Y23*$V$3)/(1800*$W$3) -> 6.1077942 | AI23: =(Z23*$V$3)/(1800*$W$3) -> 4.2141924 | AJ23: =(AA23*$V$3)/(1800*$W$3) -> 4.4184043 | AL23: 0.72916667 | AM23: =Roster!G$55+Roster!G$56+Roster!G$59+Roster!G$60+Roster!G$61 -> 39 | AN23: =Roster!H$55+Roster!H$56+Roster!H$59+Roster!H$60+Roster!H$61 -> 34 | AO23: =Roster!I$55+Roster!I$56+Roster!I$59+Roster!I$60+Roster!I$61 -> 37 | AP23: =Roster!J$55+Roster!J$56+Roster!J$59+Roster!J$60+Roster!J$61 -> 26 | AQ23: =Roster!K$55+Roster!K$56+Roster!K$59+Roster!K$60+Roster!K$61 -> 26 | AR23: =Roster!L$55+Roster!L$56+Roster!L$59+Roster!L$60+Roster!L$61 -> 27 | AS23: =Roster!M$55+Roster!M$56+Roster!M$59+Roster!M$60+Roster!M$61 -> 27 | AU23: 0.72916667 | AV23: =AM23*(1-32%) -> 26.52 | AW23: =AN23*(1-32%) -> 23.12 | AX23: =AO23*(1-32%) -> 25.16 | AY23: =AP23*(1-32%) -> 17.68 | AZ23: =AQ23*(1-32%) -> 17.68 | BA23: =AR23*(1-32%) -> 18.36 | BB23: =AS23*(1-32%) -> 18.36 | BD23: 0.72916667 | BE23: =AV23*1800*$W$3/300 -> 127.296 | BF23: =AW23*1800*$W$3/300 -> 110.976 | BG23: =AX23*1800*$W$3/300 -> 120.768 | BH23: =AY23*1800*$W$3/300 -> 84.864 | BI23: =AZ23*1800*$W$3/300 -> 84.864 | BJ23: =BA23*1800*$W$3/300 -> 88.128 | BK23: =BB23*1800*$W$3/300 -> 88.128 | BM23: 0.72916667 | BN23: =AV23-AD23 -> 19.298322 | BO23: =AW23-AE23 -> 16.343876 | BP23: =AX23-AF23 -> 19.609148 | BQ23: =AY23-AG23 -> 10.681099 | BR23: =AZ23-AH23 -> 11.572206 | BS23: =BA23-AI23 -> 14.145808 | BT23: =BB23-AJ23 -> 13.941596 | BV23: 0.72916667 | BW23: =BE23-U23 -> 92.631947 | BX23: =BF23-V23 -> 78.450603 | BY23: =BG23-W23 -> 94.123908 | BZ23: =BH23-X23 -> 51.269275 | CA23: =BI23-Y23 -> 55.546588 | CB23: =BJ23-Z23 -> 67.899877 | CC23: =BK23-AA23 -> 66.919659
